Workbook
Name BattCellCapacity: '规格书 Datasheet'!$C$5
Name BattCellCapacity_BK: '备用电池箱 Spare Accumulator'!$C$6
Name BattCellMaxV: '规格书 Datasheet'!$C$6
Name BattCellMaxV_BK: '备用电池箱 Spare Accumulator'!$C$7
Name BattCellNomV: '规格书 Datasheet'!$C$7
Name BattCellNomV_BK: '备用电池箱 Spare Accumulator'!$C$8
Name BusCap: '预充电放电 PrechargeDischarge'!$D$10
Name CellsPerTempSensor: '电池箱 Accumulator'!$O$25
Name CellsPerTempSensor_BK: '备用电池箱 Spare Accumulator'!$O$39
Name ConnectorNames: '规格书 Datasheet'!$B$74:$B$92
Name ConnectorsTable: '规格书 Datasheet'!$A$74:$H$92
Name ConnectorTable: '规格书 Datasheet'!$B$74:$H$92
Name ContactorNames: '规格书 Datasheet'!$B$66:$B$70
Name ContactorsTable: '规格书 Datasheet'!$B$66:$H$70
Name DischargeRes: '预充电放电 PrechargeDischarge'!$J$6
Name ErrorText: "WARNING"
Name FuseName: '规格书 Datasheet'!$B$42:$B$53
Name FuseNames: '规格书 Datasheet'!$B$42:$B$53
Name FuseNoiCur: '电池箱 Accumulator'!$U$20
Name FuseNoiCur_BK: '备用电池箱 Spare Accumulator'!$U$34
Name FusesTable: '规格书 Datasheet'!$B$42:$H$53
Name FuseTable: '规格书 Datasheet'!$B$42:$H$53
Name IncompleteText: "BLANK"
Name InsulationNames: '规格书 Datasheet'!$B$96:$B$105
Name InsulationsTable: '规格书 Datasheet'!$B$96:$I$105
Name MaxTSVoltage: '电池箱 Accumulator'!$E$4
Name MaxTSVoltage_BK: '备用电池箱 Spare Accumulator'!$E$18
Name NominalTSVoltage: '电池箱 Accumulator'!$E$5
Name NominalTSVoltage_BK: '备用电池箱 Spare Accumulator'!$E$19
Name OKText: "OK"
Name PrechargeRes: '预充电放电 PrechargeDischarge'!$D$6
Name ResistorsNames: '规格书 Datasheet'!$B$57:$B$62
Name ResistorsTable: '规格书 Datasheet'!$B$57:$H$62
Name TotalCells: '电池箱 Accumulator'!$E$6
Name TotalCells_BK: '备用电池箱 Spare Accumulator'!$E$20

Sheet 总览 Overview
A1: 文档填写要求 Document Filling Requirements | J1: 结果汇总 Status | M1: 最终结果 Overall Results
A2: - 所有橙色背景的单元格均需要填写。 - 蓝色背景的单元格是自动生成的检查结果。 - 图片必须放置在指定区域上并且高清且横纵比正常。图片需要能够被放大以进行进一步审核。 - 所有要求规格书的都应该在规定位置提供下载超链接,优先放置供应商公开网址的信息,允许车队提供的网盘,但是分享链接应当是无密码且长期有效的。链接不必完整显示在文档中。 - 禁止链接到淘宝产品介绍页面。 - 额外补充信息用于补充说明审核员提出的疑点。任何文字说明信息应该做到不惜言，不赘述。 - 完成后删除所有的此单元格以外的样例(橙色图片)/说明性文字（斜体）。 - 由于反馈更改的内容必须要标为红色。未标红视为未更改。请仅标红当前最新更改部分。 - 无论当前是否已经对ESF予以通过，任何未经许可的对自动检查表格模板的修改/破解将导致该车队本年度的电检资格取消。 - 自动检查通过并不代表ESF必然获得通过。 - 推荐使用Excel编辑，WPS可能存在格式显示错误的问题。 ———— - All cells with an orange background need to be filled out. - Cells with a blue background are automatically generated inspection results. - Images must be clear and recognizable. - All required specifications should provide download hyperlinks in the designated location. Preference should be given to publicly accessible URLs from suppliers. Cloud drives provided by the team are allowed, but the shared links should be password-free and long-term valid. The links do not need to be fully displayed in the document. - Linking to online vendor product introduction pages is prohibited. - Additional supplementary information is used to supplement the doubts raised by the auditor. Any text description information should be verbose and should not be repeated. - After completion, delete all examples (orange images)/explanatory text (italic) except for this cell. - Changes made due to feedback must be marked in red. Changes not marked in red will be considered unmodified. Please only mark the most recent changes in red. - Regardless of whether the ESF has currently been approved, any unauthorized modifications/hacks to the automated checklist template will result in the team's disqualification from the electrical inspection for the current year. - Passing the automated check does not guarantee that the ESF will be approved. - It is recommended to use Excel for editing. WPS may have format display errors. | J2: 规格书 Datasheets | K2: ='规格书 Datasheet'!B1 -> OK | M2: =IF(COUNTIF(K2:K12,"="&IncompleteText),IncompleteText,IF(COUNTIF(K2:K12,"="&ErrorText),ErrorText,OKText)) -> OK
J3: 驱动系统原理图 TS Schematics | K3: ='驱动系统原理图 TS Schematics'!$B$1 -> OK
J4: 电池箱 Accumulator | K4: ='电池箱 Accumulator'!$B$1 -> OK
J5: 备用电池箱 Spare Accumulator | K5: ='备用电池箱 Spare Accumulator'!$B$1 -> OK
J6: 预充电/放电回路 Precharge/Discharge | K6: ='预充电放电 PrechargeDischarge'!B1 -> OK
J7: 充电系统 Charging | K7: ='充电 Charging'!B1 -> OK
J8: 安全系统 Shutdown circuits | K8: ='安全系统 Shutdown circuit'!B1 -> OK
J9: 扭矩输出 Torque security | K9: ='扭矩指令 Torque Security'!B1 -> OK
J10: 其他 Other | K10: ='其他 Others'!B1 -> OK
J11: 接地 Grounding | K11: ='接地 Grounding'!B1 -> OK
J12: 车队信息 Team info | K12: =O13 -> OK
J13: 车队信息 Team info | O13: =IF(COUNTIF(O14:O16,"="&IncompleteText),IncompleteText,IF(COUNTIF(O14:O16,"="&ErrorText),ErrorText,OKText)) -> OK
J14: 学校 University | K14: 合肥工业大学 | O14: =IF(ISBLANK(K14),IncompleteText,OKText) -> OK
J15: 车队名称 Team | K15: 睿智无人车队 | O15: =IF(ISBLANK(K15),IncompleteText,OKText) -> OK
J16: 车号 Car Number | K16: A10 | O16: =IF(ISBLANK(K16),IncompleteText,OKText) -> OK
J18: 驱动系统最大电压 Max TS voltage | K18: =MaxTSVoltage -> 365.4 | L18: V
J19: 主保险丝额定电流 Accumulator | K19: =FuseNoiCur -> 60 | L19: A
A21: Additional Comment - 1 | I21: Additional Comment - 2

Sheet 规格书 Datasheet
A1: 状态 Status | B1: =IF(SUM(COUNTIF(INDIRECT({"$E$2","$I$15","$I$40","$I$55","$I$64","$I$72","$J$94"}),"="&IncompleteText))>0,IncompleteText,IF(SUM(COUNTIF(INDIRECT({"$E$2","$I$15","$I$40","$I$55","$I$64","$I$72","$J$94"}),"="&ErrorText))>0,ErrorText,OKText)) -> OK
A2: 电芯单体 Battery Cell | E2: =IF(COUNTBLANK(C3:C13)>0,IncompleteText,OKText) -> OK
A3: 制造商 Make | C3: 深圳市格瑞普电池有限公司
A4: 型号 Model | C4: GRP9885155-3.8V 15000mAh
A5: 额定容量 Nominal Capacity | C5: 15.0 | D5: Ahr
A6: 最大电压 Maximum Voltage | C6: 4.35 | D6: V
A7: 额定电压 Nominal Voltage | C7: 3.8 | D7: V
A8: 最小电压 Minimum Voltage | C8: 3.0 | D8: V
A9: 最大瞬时输出电流 Max output current | C9: 300.0 | D9: A
A10: 最大连续输出电流 Max continous current | C10: 200.0 | D10: A
A11: 最大工作温度 Max Cell temp | C11: 45.0 | D11: C
A12: 电芯化学类型 Cell Chemistry | C12: 聚合物锂离子电池
A13: 说明书超链接 Link to Datasheet | C13: 电芯_GRP9885155-3.8V 15000mAh
A15: 导体信息 Conductors | I15: =IF(COUNTIF(I17:I38,"="&IncompleteText),IncompleteText,IF(COUNTIF(I17:I38,"="&ErrorText),ErrorText,OKText)) -> OK | K15: 规则参考/注释 Rules Reference/Comment | O15: Location List
A16: 制造商 Manufacturer | B16: 型号 Part number | C16: 载流截面积 Size [mm2] | D16: 额定电压 Nominal Voltage [Vdc] | E16: 额定电流 Nominal Current [A] | F16: 最大工作温度 Max Temp[C] | G16: 说明书链接 Datasheet Hyperlink | H16: 位置 Location | I16: 判定 Auto-check | J16: 注释 Additional Info | K16: `- 如果在不同位置使用了相同的导体，请增加一行重复的输入项目。 - 如果相同段落使用了多种导体，每一种导体信息都应该被填入 - 本表格更多指向铜牌，导线等 - 如果使用位置是'其他驱动系统’，请在注释列填写说明 - 检查项目包括但不限于： -- EV 4.1 -- EV 4.5 本页表格允许添加行 ———— - If the same conductor is used in different locations, please add an additional row with the repeated input item. - If multiple types of conductors are used in the same section, information for each conductor should be filled in. - If the usage location is 'Other TS,' please provide an explanation in the Additional Info column. - Rows can be added to the table on this page. | M16: ` | O16: 电芯之间 Between cells
A17: 东莞市鑫宏泰铜材 | B17: 铜排 | C17: 45.4 | D17: 365.4 | E17: 180 | F17: 125 | G17: 铜排_电芯之间 | H17: 电芯之间 | I17: =IF(COUNTBLANK(A17:H17)=8,IncompleteText,IF(AND(COUNTBLANK(A17:H17)=0,F17>=85),IF(AND(H17="其他驱动系统",COUNTBLANK(J17)=1),ErrorText,OKText),ErrorText)) -> OK | J17: 该导体为模组正负极至维护插头之间的圆柱形铜导体。实测最小半径约3.8mm，对应直径约7.6mm，按圆形截面计算有效载流截面积为π×3.8²=45.36mm²，ESF按45.4mm²填写。导体设计持续电流为180A，对应平均电流密度约3.97A/mm²。额定电压365.4VDC为车辆最大驱动系统电压；裸铜导体的绝缘耐压由绝缘支撑、电气间隙、爬电距离及电池箱结构保证。最高工作温度按连接结构中最低额定温度的部件确定，不使用铜的1083℃熔点作为工作温度依据。 | O17: 电芯到AIR Between cells and AIR
A18: 荣缆 | B18: EVRP新能源汽车屏蔽高压线 | C18: 35 | D18: 1500 | E18: 200 | F18: 125 | G18: 荣缆_电芯到AIR | H18: 电芯到AIR | I18: =IF(COUNTBLANK(A18:H18)=8,"",IF(AND(COUNTBLANK(A18:H18)=0,F18>=85),IF(AND(H18="其他驱动系统",COUNTBLANK(J18)=1),ErrorText,OKText),ErrorText)) -> OK | O18: AIR到电池箱连接器 Between AIR and Acc Connector
A19: 荣缆 | B19: EVRP新能源汽车屏蔽高压线 | C19: 35 | D19: 1500 | E19: 200 | F19: 125 | G19: 荣缆_AIR到电池箱连接器 | H19: AIR到电池箱连接器 | I19: =IF(COUNTBLANK(A19:H19)=8,"",IF(AND(COUNTBLANK(A19:H19)=0,F19>=85),IF(AND(H19="其他驱动系统",COUNTBLANK(J19)=1),ErrorText,OKText),ErrorText)) -> OK | O19: 电池箱到电机控制器 Between Acc and Motor Controller
A20: 荣缆 | B20: EVRP新能源汽车屏蔽高压线 | C20: 35 | D20: 1500 | E20: 200 | F20: 125 | G20: 荣缆_电池箱到电机控制器 | H20: 电池箱到电机控制器 | I20: =IF(COUNTBLANK(A20:H20)=8,"",IF(AND(COUNTBLANK(A20:H20)=0,F20>=85),IF(AND(H20="其他驱动系统",COUNTBLANK(J20)=1),ErrorText,OKText),ErrorText)) -> OK | O20: 电池箱到能量计Between Acc and Energy Meter
A21: 荣缆 | B21: EVRP新能源汽车屏蔽高压线 | C21: 35 | D21: 1500 | E21: 200 | F21: 125 | G21: 荣缆_电池箱到能量计 | H21: 电池箱到能量计 | I21: =IF(COUNTBLANK(A21:H21)=8,"",IF(AND(COUNTBLANK(A21:H21)=0,F21>=85),IF(AND(H21="其他驱动系统",COUNTBLANK(J21)=1),ErrorText,OKText),ErrorText)) -> OK | O21: 能量计到电机控制器 Between Energy Meter and Motor Controller
A22: 荣缆 | B22: EVRP新能源汽车屏蔽高压线 | C22: 35 | D22: 1500 | E22: 200 | F22: 125 | G22: 荣缆_能量计到电机控制器 | H22: 能量计到电机控制器 | I22: =IF(COUNTBLANK(A22:H22)=8,"",IF(AND(COUNTBLANK(A22:H22)=0,F22>=85),IF(AND(H22="其他驱动系统",COUNTBLANK(J22)=1),ErrorText,OKText),ErrorText)) -> OK | O22: TSMP采样线 TSMP detection wires
A23: 深圳市隆晟达电线电缆实业有限公司 | B23: 3135-12AWG | C23: 3 | D23: 600 | E23: 30 | F23: 200 | G23: 3135系列_TSMP采样线 | H23: TSMP采样线 | I23: =IF(COUNTBLANK(A23:H23)=8,"",IF(AND(COUNTBLANK(A23:H23)=0,F23>=85),IF(AND(H23="其他驱动系统",COUNTBLANK(J23)=1),ErrorText,OKText),ErrorText)) -> OK | O23: TSAL采样线 TSAL detection wire
A24: 深圳市隆晟达电线电缆实业有限公司 | B24: 3135-18AWG | C24: 0.75 | D24: 600 | E24: 7 | F24: 200 | G24: 3135系列_TSAL采样线 | H24: TSAL采样线 | I24: =IF(COUNTBLANK(A24:H24)=8,"",IF(AND(COUNTBLANK(A24:H24)=0,F24>=85),IF(AND(H24="其他驱动系统",COUNTBLANK(J24)=1),ErrorText,OKText),ErrorText)) -> OK | O24: 电芯单体采样线 Cell Volt Detection
A25: 深圳市隆晟达电线电缆实业有限公司 | B25: 3135-18AWG | C25: 0.75 | D25: 600 | E25: 7 | F25: 200 | G25: 3135系列_电芯单体采样线 | H25: 电芯单体采样线 | I25: =IF(COUNTBLANK(A25:H25)=8,"",IF(AND(COUNTBLANK(A25:H25)=0,F25>=85),IF(AND(H25="其他驱动系统",COUNTBLANK(J25)=1),ErrorText,OKText),ErrorText)) -> OK | O25: 电机控制器到电机 Between Motor Controller and Motors
A26: 荣缆 | B26: EVRP新能源汽车屏蔽高压线 | C26: 35 | D26: 1500 | E26: 200 | F26: 125 | G26: 荣缆_电机控制器到电芯 | H26: 电机控制器到电机 | I26: =IF(COUNTBLANK(A26:H26)=8,"",IF(AND(COUNTBLANK(A26:H26)=0,F26>=85),IF(AND(H26="其他驱动系统",COUNTBLANK(J26)=1),ErrorText,OKText),ErrorText)) -> OK | O26: 电池箱到HVD Between ACC and HVD
A27: 荣缆 | B27: EVRP新能源汽车屏蔽高压线 | C27: 35 | D27: 1500 | E27: 200 | F27: 125 | G27: 荣缆_电池箱到HVD | H27: 电池箱到HVD | I27: =IF(COUNTBLANK(A27:H27)=8,"",IF(AND(COUNTBLANK(A27:H27)=0,F27>=85),IF(AND(H27="其他驱动系统",COUNTBLANK(J27)=1),ErrorText,OKText),ErrorText)) -> OK | O27: HVD到电机控制器, Between Motor Controller and HVD
A28: 荣缆 | B28: EVRP新能源汽车屏蔽高压线 | C28: 35 | D28: 1500 | E28: 200 | F28: 125 | G28: 荣缆_HVD到电机控制器 | H28: HVD到电机控制器 | I28: =IF(COUNTBLANK(A28:H28)=8,"",IF(AND(COUNTBLANK(A28:H28)=0,F28>=85),IF(AND(H28="其他驱动系统",COUNTBLANK(J28)=1),ErrorText,OKText),ErrorText)) -> OK | O28: 预充电回路 Precharge
A29: 深圳市隆晟达电线电缆实业有限公司 | B29: 3135-12AWG | C29: 3 | D29: 600 | E29: 30 | F29: 200 | G29: 3135系列_预充电回路 | H29: 预充电回路 | I29: =IF(COUNTBLANK(A29:H29)=8,"",IF(AND(COUNTBLANK(A29:H29)=0,F29>=85),IF(AND(H29="其他驱动系统",COUNTBLANK(J29)=1),ErrorText,OKText),ErrorText)) -> OK | O29: 放电回路 Discharge
... A32: 深圳市隆晟达电线电缆实业有限公司 | B32: 3135-12AWG | C32: 3 | D32: 600 | E32: 30 | F32: 200 | G32: 3135系列_充电机AC侧 | H32: 充电机AC侧 | I32: =IF(COUNTBLANK(A32:H32)=8,"",IF(AND(COUNTBLANK(A32:H32)=0,F32>=85),IF(AND(H32="其他驱动系统",COUNTBLANK(J32)=1),ErrorText,OKText),ErrorText)) -> OK | O32: 其他驱动系统 Other TS
A33: 深圳市隆晟达电线电缆实业有限公司 | B33: 3239-24AWG | C33: 0.2 | D33: 3000 | E33: 2 | F33: 200 | G33: 3239系列_安全回路 | H33: 安全回路 | I33: =IF(COUNTBLANK(A33:H33)=8,"",IF(AND(COUNTBLANK(A33:H33)=0,F33>=85),IF(AND(H33="其他驱动系统",COUNTBLANK(J33)=1),ErrorText,OKText),ErrorText)) -> OK | J33: 包含信号线 | O33: 安全回路 Shutdown circuit
A34: 深圳市隆晟达电线电缆实业有限公司 | B34: 3239-20AWG | C34: 0.5 | D34: 3000 | E34: 5 | F34: 200 | G34: 3239系列_其他低压系统 Other LVS | H34: 其他低压系统 Other LVS | I34: =IF(COUNTBLANK(A34:H34)=8,"",IF(AND(COUNTBLANK(A34:H34)=0,F34>=85),IF(AND(H34="其他驱动系统",COUNTBLANK(J34)=1),ErrorText,OKText),ErrorText)) -> OK | J34: 应用位置：VCU信号线与电源线，硬件电路连接线，无人传感器连接线 | O34: 其他低压系统 Other LVS
A35: 荣缆 | B35: EVRP新能源汽车屏蔽高压线 | C35: 35 | D35: 1500 | E35: 200 | F35: 125 | G35: 荣缆_其他驱动系统 Other TS | H35: 其他驱动系统 Other TS | I35: =IF(COUNTBLANK(A35:H35)=8,"",IF(AND(COUNTBLANK(A35:H35)=0,F35>=85),IF(AND(H35="其他驱动系统",COUNTBLANK(J35)=1),ErrorText,OKText),ErrorText)) -> OK | J35: 应用位置：主保险丝连接、Air连接，主接插件、HVD、能量计、电机控制器、电机间连接线
A36: CNXI华西科技 | B36: SC35-6 | C36: 35 | D36: 365.4 | E36: 170 | F36: 200 | G36: 直铜鼻_其他驱动系统 Other TS | H36: 其他驱动系统 Other TS | I36: =IF(COUNTBLANK(A36:H36)=8,"",IF(AND(COUNTBLANK(A36:H36)=0,F36>=85),IF(AND(H36="其他驱动系统",COUNTBLANK(J36)=1),ErrorText,OKText),ErrorText)) -> OK | J36: 应用位置：主保险丝连接、Air连接，主接插件连接、HVD连接、能量计连接、电机控制器连接、电机间连接。温度参数来源及证明：CNXI产品资料表明，该端子本体材料为铜/紫铜，表面处理为镀锡（Terminal Body: Copper；Plating: Tin）。厂家另行确认该类紫铜镀锡端子的最高温度能力为200 ℃，因此ESF中的Max Temp填写为200 ℃。其中，CNXI产品资料用于证明端子的材料和镀层结构，200 ℃数值以厂家提供的温度能力说明为依据。该温度未列在CNXI公开产品页面中，也不是根据锡的熔点或材料性质自行推导所得。 电压参数来源及证明：车辆动力电池由84个电芯串联组成，单体电芯最高电压为4.35 V，因此牵引系统最大应用电压为： 84 × 4.35 V = 365.4 Vdc 故ESF中的Nominal Voltage填写为365.4 Vdc。该数值来源于车辆动力电池串联数量和单体最高电压，是端子在整车中的最大应用电压，不是厂家对裸铜端子给出的独立额定耐压。端子本体属于裸露导电连接件，不承担绝缘功能；其在365.4 Vdc系统中的电气安全由安装后的热缩管、绝缘护套、防护罩、电气间隙和爬电距离共同保证。
A37: CNXI华西科技 | B37: T90-35-6 | C37: 35 | D37: 365.4 | E37: 170 | F37: 200 | G37: 直角铜鼻_其他驱动系统 Other TS | H37: 其他驱动系统 Other TS | I37: =IF(COUNTBLANK(A37:H37)=8,"",IF(AND(COUNTBLANK(A37:H37)=0,F37>=85),IF(AND(H37="其他驱动系统",COUNTBLANK(J37)=1),ErrorText,OKText),ErrorText)) -> OK | J37: 应用位置：维护插头到主保险丝走线，主保险丝连接，Air连接，主接插件与HVD间走线。温度参数来源及证明：CNXI产品资料表明，该端子本体材料为铜/紫铜，表面处理为镀锡（Terminal Body: Copper；Plating: Tin）。厂家另行确认该类紫铜镀锡端子的最高温度能力为200 ℃，因此ESF中的Max Temp填写为200 ℃。其中，CNXI产品资料用于证明端子的材料和镀层结构，200 ℃数值以厂家提供的温度能力说明为依据。该温度未列在CNXI公开产品页面中，也不是根据锡的熔点或材料性质自行推导所得。 电压参数来源及证明：车辆动力电池由84个电芯串联组成，单体电芯最高电压为4.35 V，因此牵引系统最大应用电压为： 84 × 4.35 V = 365.4 Vdc 故ESF中的Nominal Voltage填写为365.4 Vdc。该数值来源于车辆动力电池串联数量和单体最高电压，是端子在整车中的最大应用电压，不是厂家对裸铜端子给出的独立额定耐压。端子本体属于裸露导电连接件，不承担绝缘功能；其在365.4 Vdc系统中的电气安全由安装后有效绝缘共同保证。
I38: =IF(COUNTBLANK(A38:H38)=8,"",IF(AND(COUNTBLANK(A38:H38)=0,F38>=85),IF(AND(H38="其他驱动系统",COUNTBLANK(J38)=1),ErrorText,OKText),ErrorText))
A40: 过流保护器件 Fuses | I40: =IF(COUNTIF(I42:I53,"="&IncompleteText),IncompleteText,IF(COUNTIF(I42:I53,"="&ErrorText),ErrorText,OKText)) -> OK | J40: 规则参考/注释 Rules Reference/Comment
A41: 制造商 Manufacturer | B41: 型号 Part number | C41: 额定电压Nominal Voltage [Vdc] | D41: 额定电流 Nominal Current [A] | E41: 额定分断电流 Interrupt (A) | F41: 最大工作温度 Max Temp[C] | G41: =G16 -> 说明书链接 Datasheet Hyperlink | H41: =H16 -> 位置 Location | I41: 判定 Auto-check | J41: 注释 Additional Info | K41: - 如果使用位置是'其他驱动系统’，请在注释列填写说明，且关于位置的表述必须和之前的导体段落文本完全一致 - 检查的项目包括但不限于 - EV 3.2 ———— If the usage location is 'Other TS,' please provide an explanation in the Additional Info column. It must the same as the expression in the 'Conductor' part
A42: Bussmann | B42: FWH-60B | C42: 500 | D42: 60 | E42: 50000 | F42: 200 | G42: FWH 500V系列规格书_电芯到AIR Between cells and AIR | H42: 电芯到AIR Between cells and AIR | I42: =IF(COUNTBLANK(A42:H42)=8,IncompleteText,IF(AND(COUNTBLANK(A42:H42)=0,F42>=85),IF(AND(H42="其他驱动系统",COUNTBLANK(J42)=1),ErrorText,OKText),ErrorText)) -> OK
A43: Bussmann | B43: FWP-60C | C43: 700 | D43: 60 | E43: 50000 | F43: 200 | G43: FWP-700V系列规格书_电池箱到电机控制器 Between Acc and Motor Controller | H43: 电池箱到电机控制器 Between Acc and Motor Controller | I43: =IF(COUNTBLANK(A43:H43)=8,"",IF(AND(COUNTBLANK(A43:H43)=0,F43>=85),IF(AND(H43="其他驱动系统",COUNTBLANK(J43)=1),ErrorText,OKText),ErrorText)) -> OK
A44: Littelfuse | B44: 0466.250NRHF | C44: 125 | D44: 0.25 | E44: 50 | F44: 90 | G44: 466 Series 1206 Fast-Acting Fuse_电芯单体采样线 Cell Volt Detection | H44: 电芯单体采样线 Cell Volt Detection | I44: =IF(COUNTBLANK(A44:H44)=8,"",IF(AND(COUNTBLANK(A44:H44)=0,F44>=85),IF(AND(H44="其他驱动系统",COUNTBLANK(J44)=1),ErrorText,OKText),ErrorText)) -> OK
...

Sheet 驱动系统原理图 TS Schematics
A1: 状态 Status | B1: {=IF(SUM(COUNTIF(INDIRECT({"$K$28","$W$28","$K$48"}),"="&IncompleteText)),IncompleteText,IF(SUM(COUNTIF(INDIRECT({"$K$28","$W$28","$K$48"}),"="&ErrorText)),ErrorText,OKText))} -> OK
A2: 电池以外驱动系统原理图 Vehicle Tractive Schematics | M2: 电池箱内部原理图 请参考左图尺寸插入图片 Internal schematic diagram of the accumulator box Please refer to the dimensions of the left diagram to insert the image. | Y2: 补充内容 Additional comments
Y3: 能量计预留电压检测线插头型号（Molex 39299023）为官方说明书中信息
A28: 电池以外驱动系统原理图 Vehicle Tractive Schematics | K28: =IF(COUNTIF(K30:K46,"="&IncompleteText),IncompleteText,IF(COUNTIF(K30:K46,"="&ErrorText),ErrorText,OKText)) -> OK | M28: 电池箱内部原理图 Accumulator TS Schematic | W28: =IF(COUNTIF(W30:W43,"="&IncompleteText),IncompleteText,IF(COUNTIF(W30:W43,"="&ErrorText),ErrorText,OKText)) -> OK
A29: 规则参考 Rules Ref | M29: 规则参考 Rules Ref
C30: 展示电池箱以外驱动系统所有细节 Show details of all TS outside of accumulator | J30: TRUE | K30: =IF(ISBLANK(J30),IncompleteText,IF(J30,OKText,ErrorText)) -> OK | O30: 电池箱内部驱动系统细节 Details of all TS circuits within accumulator | V30: TRUE | W30: =IF(ISBLANK(V30),IncompleteText,IF(V30,OKText,ErrorText)) -> OK
C31: 电池箱被作为一个整体呈现(AIR除外) Accumulator is shown as a single element (without internal details) | J31: TRUE | K31: =IF(ISBLANK(J31),IncompleteText,IF(J31,OKText,ErrorText)) -> OK | O31: 所有的线径都有标注 All wire gauges labeled | V31: TRUE | W31: =IF(ISBLANK(V31),IncompleteText,IF(V31,OKText,ErrorText)) -> OK
A32: EV 4.5.5 | C32: 所有的线径都有标注 All wire guages labeled | J32: TRUE | K32: =IF(ISBLANK(J32),IncompleteText,IF(J32,OKText,ErrorText)) -> OK | O32: 所有的保险丝都有标注额定电流 All fuses are labeled with their ampacity | V32: TRUE | W32: =IF(ISBLANK(V32),IncompleteText,IF(V32,OKText,ErrorText)) -> OK
C33: 所有的保险丝都有标注额定电流 All fuses labedled with ampacity | J33: TRUE | K33: =IF(ISBLANK(J33),IncompleteText,IF(J33,OKText,ErrorText)) -> OK | O33: 保险丝距离电源侧线缆的距离(未保护线缆长度）Distance from fuses to positive power souces | V33: TRUE | W33: =IF(ISBLANK(V33),IncompleteText,IF(V33,OKText,ErrorText)) -> OK
C34: 保险丝位置应当对应其真实物理位置（壳体）Fuse locations represent physical location | J34: TRUE | K34: =IF(ISBLANK(J34),IncompleteText,IF(J34,OKText,ErrorText)) -> OK | O34: 保险丝位置应当对应其真实物理位置 Fuse locations represent physical location | V34: TRUE | W34: =IF(ISBLANK(V34),IncompleteText,IF(V34,OKText,ErrorText)) -> OK
A35: EV 4.2 | C35: 驱动系统壳体 TS enclosures | J35: TRUE | K35: =IF(ISBLANK(J35),IncompleteText,IF(J35,OKText,ErrorText)) -> OK | O35: 接插件标注有制造商/型号 Connectors labeled with Make/Model | V35: TRUE | W35: =IF(ISBLANK(V35),IncompleteText,IF(V35,OKText,ErrorText)) -> OK
C36: 接插件标注有制造商/型号 Connectors labeled with Make/Model | J36: TRUE | K36: =IF(ISBLANK(J36),IncompleteText,IF(J36,OKText,ErrorText)) -> OK | O36: 使用通用的原理图符号 Standard schematic symbols used | V36: TRUE | W36: =IF(ISBLANK(V36),IncompleteText,IF(V36,OKText,ErrorText)) -> OK
C37: 使用通用的原理图符号 Standard schematic symbols used | J37: TRUE | K37: =IF(ISBLANK(J37),IncompleteText,IF(J37,OKText,ErrorText)) -> OK | O37: 文字放大后清晰 All text iis readable, zooming allowed | V37: TRUE | W37: =IF(ISBLANK(V37),IncompleteText,IF(V37,OKText,ErrorText)) -> OK
C38: 文字放大后清晰 All text iis readable, zooming allowed | J38: TRUE | K38: =IF(ISBLANK(J38),IncompleteText,IF(J38,OKText,ErrorText)) -> OK | M38: EV 5.6 | O38: AIRs | V38: TRUE | W38: =IF(ISBLANK(V38),IncompleteText,IF(V38,OKText,ErrorText)) -> OK
A39: EV 4.7 | C39: TSMPs | J39: TRUE | K39: =IF(ISBLANK(J39),IncompleteText,IF(J39,OKText,ErrorText)) -> OK | M39: EV 5.4.4 - EV 5.4.5 | O39: 维护插头 Maintenance plugs | V39: TRUE | W39: =IF(ISBLANK(V39),IncompleteText,IF(V39,OKText,ErrorText)) -> OK
C40: 电机控制器 Motor controllers | J40: TRUE | K40: =IF(ISBLANK(J40),IncompleteText,IF(J40,OKText,ErrorText)) -> OK | O40: 电芯（电芯互联的部分可以简略）Cells (intercell connections may be abstracted) | V40: TRUE | W40: =IF(ISBLANK(V40),IncompleteText,IF(V40,OKText,ErrorText)) -> OK
C41: 电机 Motors | J41: TRUE | K41: =IF(ISBLANK(J41),IncompleteText,IF(J41,OKText,ErrorText)) -> OK | M41: EV 5.4.8 - EV 5.4.10 | O41: 电池箱高压指示器 High voltage indicator | V41: TRUE | W41: =IF(ISBLANK(V41),IncompleteText,IF(V41,OKText,ErrorText)) -> OK
A42: EV 4.7.6 | C42: TSMP没有熔断 TSMP not fused | J42: TRUE | K42: =IF(ISBLANK(J42),IncompleteText,IF(J42,OKText,ErrorText)) -> OK | M42: EV 5.7 | O42: 预充电回路 Precharge circuit | V42: TRUE | W42: =IF(ISBLANK(V42),IncompleteText,IF(V42,OKText,ErrorText)) -> OK
A43: EV 4.6 | C43: 数据记录仪 Energy Meter/Data Logger | J43: TRUE | K43: =IF(ISBLANK(J43),IncompleteText,IF(J43,OKText,ErrorText)) -> OK | O43: 预充电回路过流保护 precharge circuit overcurrent protections | V43: TRUE | W43: =IF(ISBLANK(V43),IncompleteText,IF(V43,OKText,ErrorText)) -> OK
A44: EV 4.9 | C44: 放电回路 Discharge circuit | J44: TRUE | K44: =IF(ISBLANK(J44),IncompleteText,IF(J44,OKText,ErrorText)) -> OK
A45: EV 4.9.3 | C45: 放电回路未熔断 Discharge not fused | J45: TRUE | K45: =IF(ISBLANK(J45),IncompleteText,IF(J45,OKText,ErrorText)) -> OK
A46: EV 4.8 | C46: HVD | J46: TRUE | K46: =IF(ISBLANK(J46),IncompleteText,IF(J46,OKText,ErrorText)) -> OK
A48: 至少在其中一副原理图中展示 Must shown on at least one schematic | K48: =IF(COUNTIF(K50:K50,"="&IncompleteText),IncompleteText,IF(COUNTIF(K50:K50,"="&ErrorText),ErrorText,OKText)) -> OK
A49: 规则参考 Rules Ref
A50: EV 6.4 | C50: IMD | J50: TRUE | K50: =IF(ISBLANK(J50),IncompleteText,IF(J50,OKText,ErrorText)) -> OK

Sheet 电池箱 Accumulator
A1: 状态 Status | B1: =IF(SUM(COUNTIF(INDIRECT({"$G$3","$G$4","$G$5","$J$8","$Q$8","$W$8","$AD$8","$AK$8","$Z$52","$Q$52","$H$52","$AI$52","$AR$52","$BA$52","$Q$83","$H$83"}),"="&IncompleteText)),IncompleteText,IF(SUM(COUNTIF(INDIRECT({"$G$3","$G$4","$G$5","$J$8","$Q$8","$W$8","$AD$8","$AK$8","$Z$52","$Q$52","$H$52","$AI$52","$AR$52","$BA$52","$Q$83","$H$83"}),"="&ErrorText)),ErrorText,OKText)) -> OK
A3: 模组连接关系 Segment-to-Segment Connection | E3: 串联 Serial | G3: =IF(ISBLANK(E3),IncompleteText,OKText) -> OK
A4: 驱动系统最大电压 Max TS voltage | E4: {=IF(E3="串联 Serial",SUM(C12:C29)*BattCellMaxV,C12*BattCellMaxV*SUM(IF(FREQUENCY(E12:E29,E12:E29)>0,1)))} -> 365.4 | F4: V | G4: =IF(MaxTSVoltage=0,IncompleteText,IF(E4>600,ErrorText,OKText)) -> OK
A5: 驱动系统额定电压 Nominal TS voltage | E5: {=IF(E3="串联 Serial",SUM(C12:C29)*BattCellNomV,C12*BattCellNomV*SUM(IF(FREQUENCY(E12:E29,E12:E29)>0,1)))} -> 319.2 | F5: V | G5: =IF(MaxTSVoltage=0,IncompleteText,IF(E5>600,ErrorText,OKText)) -> OK
A6: 电池单体数量 Total cells | E6: =SUMPRODUCT(B12:B29,C12:C29) -> 84
A8: 模组数据 Segement data | J8: =IF(COUNTIF(J9:J29,"="&IncompleteText),IncompleteText,IF(COUNTIF(J9:J29,"="&ErrorText),ErrorText,OKText)) -> OK | K8: BMS | Q8: =IF(COUNTIF(Q9:Q30,"="&IncompleteText),IncompleteText,IF(COUNTIF(Q9:Q30,"="&ErrorText),ErrorText,OKText)) -> OK | R8: 维护插头 Maintenance Plugs | W8: =IF(COUNTIF(W9:W21,"="&IncompleteText),IncompleteText,IF(COUNTIF(W9:W21,"="&ErrorText),ErrorText,OKText)) -> OK | X8: 绝缘材料 Insulating Materials | AD8: =IF(COUNTIF(AD9:AD18,"="&IncompleteText),IncompleteText,IF(COUNTIF(AD9:AD18,"="&ErrorText),ErrorText,OKText)) -> OK | AE8: [全车]自制PCB高低压隔离 High and low voltage isolation in [all] PCBs | AK8: =IF(AI9="否 No",OKText,IF(COUNTIF(AK9:AK13,"="&IncompleteText),IncompleteText,IF(COUNTIF(AK9:AK13,"="&ErrorText),ErrorText,OKText))) -> OK | AM8: [全车]自制PCB高低压隔离 High and low voltage isolation in [all] PCBs | AU8: 补充说明 Additional Comments
A9: 电芯串并关系 Cell connection order | D9: 先串后并 Serial then parallel | J9: =IF(ISBLANK(D9),IncompleteText,OKText) -> OK | K9: BMS拓扑 BMS Type | O9: 分布式 Distributed | Q9: =IF(ISBLANK(O9),IncompleteText,OKText) -> OK | R9: 接插件/连接器 Connector | U9: RL00801-50 | W9: =IF(ISBLANK(U9),IncompleteText,OKText) -> OK | X9: 电芯及电池箱内壁之间绝缘材料 Between cells and accumulator | AB9: FORMEX GK-17BK | AD9: =IF(ISBLANK(AB9),IncompleteText,OKText) -> OK | AE9: 全车是否有自制同时带高压和低压的PCB Does the entire vehicle contain any custom-made PCBs that handle both TS&LVS? | AI9: 否 No | AK9: =IF(ISBLANK(AI9),IncompleteText,OKText) -> OK | AM9: 展示所有同时包含高低压的PCB的爬电距离和电气间隙，若整车自制PCB没有同时存在TS&LVS，则忽略本条 Displays creepage and clearance distances for all PCBs containing both TS and LVS | AU9: 分隔电芯与主保险丝和air的绝缘材料已在对应板块补充说明部分说明；温度传感器方案已改为使用导热胶与极耳直接接触；补充电压指示器的实际安装位置图片；各部分补充说明文字已修改
A10: 模组编号 Segement | B10: 并联数 Parallel cells | C10: 串联数 Serial cells | D10: 温度测点数量 Temp sensors | E10: 电池箱编号 Accumulator number | F10: 模组最大电压 Max Voltage[V] | H10: 模组能量 Segement energy [MJ] | K10: BMS来源 BMS source | O10: 供应商提供 From Suppliers | Q10: =IF(ISBLANK(O10),IncompleteText,OKText) -> OK | R10: 额定电流 Ampacity | U10: =VLOOKUP(U9,ConnectorTable,3,FALSE) -> 200 | V10: A | W10: =IF(ISERROR(U10),IncompleteText,IF(E3="串联 Serial",IF(U10>=U20,OKText,ErrorText),IF(E3="并联 Parallel",IF(U10>=U12,OKText,ErrorText),IncompleteText))) -> OK | X10: 电压等级 Voltage Rating | AB10: =VLOOKUP(AB9,InsulationsTable,4,FALSE) -> 513.42 | AC10: V | AD10: =IF(ISERROR(AB10),IncompleteText,IF(AB10<MaxTSVoltage,ErrorText,OKText)) -> OK | AE10: 驱动系统电压范围 Drive system voltage range | AI10: 300V-600V | AK10: =IF(ISBLANK(AI10),IncompleteText,OKText) -> OK
K11: 制造商 Vendor | L11: 拓渝科技 | N11: 型号 Type | O11: TY-BMS2601 | Q11: =IF(O10="供应商提供 From Suppliers",IF(OR(ISBLANK(L11),ISBLANK(O11)),IncompleteText,OKText),"") -> OK | R11: 对应保险丝 Fuse provides protections | U11: FWH-60B | W11: =IF(E3="串联 Serial","",IF(ISBLANK(U11),IncompleteText,OKText)) | X11: 温度等级 Temperature Rating | AB11: =VLOOKUP(AB9,InsulationsTable,5,FALSE) -> 115 | AC11: C | AD11: =IF(ISERROR(AB11),IncompleteText,IF(AB11<90,ErrorText,OKText)) -> OK | AE11: 爬电距离计算值 Calculated creepage distance | AI11: 7.508 | AJ11: mm | AK11: =IF(ISBLANK(AI11),IncompleteText,OKText) -> OK
A12: 1 | B12: 1 | C12: 21 | D12: 8 | E12: 1 | F12: =C12*BattCellMaxV -> 91.35 | H12: =F12*B12*BattCellCapacity*0.0036 -> 4.9329 | J12: =IF(COUNTBLANK(A12:E12)>0,IncompleteText,IF(OR(F12>120,H12>6),ErrorText,OKText)) -> OK | K12: 驱动系统到低压控制系统绝缘电压 Galvanic Isolation TS to LVS | O12: 3000 | P12: V | Q12: =IF(ISBLANK(O12),IncompleteText,IF(O12<E4,ErrorText,OKText)) -> OK | R12: 保险丝额定电流 Fuse ampacity | U12: =VLOOKUP(U11,FuseTable,3,FALSE) -> 60 | V12: A | X12: 电芯上方覆盖 On top of cells | AB12: FORMEX GK-17BK | AD12: =IF(ISBLANK(AB12),IncompleteText,OKText) -> OK | AE12: 电气间隙计算值 Calculated electrical clearance | AI12: 7.508 | AJ12: mm | AK12: =IF(ISBLANK(AI12),IncompleteText,OKText) -> OK
A13: 2 | B13: 1 | C13: 21 | D13: 8 | E13: 1 | F13: =C13*BattCellMaxV -> 91.35 | H13: =F13*B13*BattCellCapacity*0.0036 -> 4.9329 | J13: =IF(COUNTBLANK(A13:E13)=4,"",IF(COUNTBLANK(A13:E13)>0,IncompleteText,IF(OR(F13>120,H13>6),ErrorText,OKText))) -> OK | K13: 模组间绝缘电压 Galvanic Isolation between segments | O13: 13125 | P13: V | Q13: =IF(ISBLANK(O13),IncompleteText,IF(O13<MAX(F12:G29),ErrorText,OKText)) -> OK | R13: AIR | X13: 电压等级 Voltage Rating | AB13: =VLOOKUP(AB12,InsulationsTable,4,FALSE) -> 513.42 | AC13: V | AD13: =IF(ISERROR(AB13),IncompleteText,IF(AB13<MaxTSVoltage,ErrorText,OKText)) -> OK | AE13: 是否三防胶覆盖 If covered with conformal coating | AI13: 否 No | AK13: =IF(ISBLANK(AI13),IncompleteText,OKText) -> OK
A14: 3 | B14: 1 | C14: 21 | D14: 8 | E14: 1 | F14: =C14*BattCellMaxV -> 91.35 | H14: =F14*B14*BattCellCapacity*0.0036 -> 4.9329 | J14: =IF(COUNTBLANK(A14:E14)=4,"",IF(COUNTBLANK(A14:E14)>0,IncompleteText,IF(OR(F14>120,H14>6),ErrorText,OKText))) -> OK | K14: 隔离器件 Galvanic Isolation devices | Q14: =IF($O$10="车队自制 Team design",IF(ISBLANK(O14),IncompleteText,OKText),"") | R14: 型号 Make/Model | U14: EVL250-HAD | W14: =IF(ISBLANK(U14),IncompleteText,OKText) -> OK | X14: 温度等级 Temperature Rating | AB14: =VLOOKUP(AB12,InsulationsTable,5,FALSE) -> 115 | AC14: C | AD14: =IF(ISERROR(AB14),IncompleteText,IF(AB14<90,ErrorText,OKText)) -> OK
A15: 4 | B15: 1 | C15: 21 | D15: 8 | E15: 1 | F15: =C15*BattCellMaxV -> 91.35 | H15: =F15*B15*BattCellCapacity*0.0036 -> 4.9329 | J15: =IF(COUNTBLANK(A15:E15)=4,"",IF(COUNTBLANK(A15:E15)>0,IncompleteText,IF(OR(F15>120,H15>6),ErrorText,OKText))) -> OK | K15: 隔离器件说明书 Galvanic Isolation devices datasheets | Q15: =IF($O$10="车队自制 Team design",IF(ISBLANK(O15),IncompleteText,OKText),"") | R15: 触点额定电压 Contactnoimal volatge | U15: =VLOOKUP(U14,ContactorsTable,2,FALSE) -> 900 | V15: Vdc | W15: =IF(ISERROR(U15),IncompleteText,IF(U15<MaxTSVoltage,ErrorText,OKText)) -> OK | X15: AIR,主保险丝与电芯之间 Between AIRs and Cells | AB15: FORMEX GK-17BK | AD15: =IF(ISBLANK(AB15),IncompleteText,OKText) -> OK
A16: 5 | F16: =C16*BattCellMaxV -> 0 | H16: =F16*B16*BattCellCapacity*0.0036 -> 0 | J16: =IF(COUNTBLANK(A16:E16)=4,"",IF(COUNTBLANK(A16:E16)>0,IncompleteText,IF(OR(F16>120,H16>6),ErrorText,OKText))) | K16: 电芯电压测量 Voltage Sense Leads | R16: 最大分断电流 Max switching current | U16: =VLOOKUP(U14,ContactorsTable,4,FALSE) -> 2000 | V16: A | X16: 电压等级 Voltage Rating | AB16: =VLOOKUP(AB15,InsulationsTable,4,FALSE) -> 513.42 | AC16: V | AD16: =IF(ISERROR(AB16),IncompleteText,IF(AB16<MaxTSVoltage,ErrorText,OKText)) -> OK
A17: 6 | F17: =C17*BattCellMaxV -> 0 | H17: =F17*B17*BattCellCapacity*0.0036 -> 0 | J17: =IF(COUNTBLANK(A17:E17)=4,"",IF(COUNTBLANK(A17:E17)>0,IncompleteText,IF(OR(F17>120,H17>6),ErrorText,OKText))) | K17: 最长采样线线缆长度 Max lead length | O17: 40 | P17: cm | Q17: =IF(ISBLANK(O17),IncompleteText,OKText) -> OK | R17: 额定电流 Max continuous current | U17: =VLOOKUP(U14,ContactorsTable,3,FALSE) -> 250 | V17: A | W17: =IF(ISERROR(U17),IncompleteText,IF(U17>=U20,OKText,ErrorText)) -> OK | X17: 温度等级 Temperature Rating | AB17: =VLOOKUP(AB15,InsulationsTable,5,FALSE) -> 115 | AC17: C | AD17: =IF(ISERROR(AB17),IncompleteText,IF(AB17<90,ErrorText,OKText)) -> OK
A18: 7 | F18: =C18*BattCellMaxV -> 0 | H18: =F18*B18*BattCellCapacity*0.0036 -> 0 | J18: =IF(COUNTBLANK(A18:E18)=4,"",IF(COUNTBLANK(A18:E18)>0,IncompleteText,IF(OR(F18>120,H18>6),ErrorText,OKText))) | K18: 采样线过流保护器件型号 Sense lead overprotection device | O18: 0466.250NRHF | Q18: =IF(ISBLANK(O18),IncompleteText,OKText) -> OK | R18: 主保险丝 Main Fuse | X18: 防火等级 Flammability Rating | AB18: =VLOOKUP(AB15,InsulationsTable,6,FALSE) -> UL 94V-0 | AD18: =IF(ISNA(AB18),IncompleteText,OKText) -> OK
A19: 8 | F19: =C19*BattCellMaxV -> 0 | H19: =F19*B19*BattCellCapacity*0.0036 -> 0 | J19: =IF(COUNTBLANK(A19:E19)=4,"",IF(COUNTBLANK(A19:E19)>0,IncompleteText,IF(OR(F19>120,H19>6),ErrorText,OKText))) | K19: 过流保护器件位置 Overcurrent protection device location | O19: BMS PCB | Q19: =IF(ISBLANK(O19),IncompleteText,OKText) -> OK | R19: 主保险丝 Main Fuse | U19: FWH-60B | W19: =IF(ISBLANK(U19),IncompleteText,OKText) -> OK
A20: 9 | F20: =C20*BattCellMaxV -> 0 | H20: =F20*B20*BattCellCapacity*0.0036 -> 0 | J20: =IF(COUNTBLANK(A20:E20)=4,"",IF(COUNTBLANK(A20:E20)>0,IncompleteText,IF(OR(F20>120,H20>6),ErrorText,OKText))) | K20: 其他位置说明 | Q20: =IF(O19="其他 Other",IF(ISBLANK(O20),IncompleteText,OKText),"") | R20: 额定电流 Max fuse ampacity | U20: =VLOOKUP(U19,FuseTable,3,FALSE) -> 60 | V20: A
A21: 10 | F21: =C21*BattCellMaxV -> 0 | H21: =F21*B21*BattCellCapacity*0.0036 -> 0 | J21: =IF(COUNTBLANK(A21:E21)=4,"",IF(COUNTBLANK(A21:E21)>0,IncompleteText,IF(OR(F21>120,H21>6),ErrorText,OKText))) | K21: 过流保护电压等级 Overcurrent voltage rating | O21: =VLOOKUP(O18,FuseTable,2,FALSE) -> 125 | Q21: =IF(ISERROR(O21),IncompleteText,IF(AND(O21<MAX(F12:G29),O9="集中式 Centralized"),ErrorText,OKText)) -> OK | R21: 额定电压 Main fuse voltage | U21: =VLOOKUP(U19,FuseTable,2,FALSE) -> 500 | V21: V | W21: =IF(U21<MaxTSVoltage,ErrorText,OKText) -> OK
A22: 11 | F22: =C22*BattCellMaxV -> 0 | H22: =F22*B22*BattCellCapacity*0.0036 -> 0 | J22: =IF(COUNTBLANK(A22:E22)=4,"",IF(COUNTBLANK(A22:E22)>0,IncompleteText,IF(OR(F22>120,H22>6),ErrorText,OKText))) | K22: 温度传感器
A23: 12 | F23: =C23*BattCellMaxV -> 0 | H23: =F23*B23*BattCellCapacity*0.0036 -> 0 | J23: =IF(COUNTBLANK(A23:E23)=4,"",IF(COUNTBLANK(A23:E23)>0,IncompleteText,IF(OR(F23>120,H23>6),ErrorText,OKText))) | K23: 温度传感器位置 Temp sensor location | O23: 极耳 Cell tabs | Q23: =IF(ISBLANK(O23),IncompleteText,OKText) -> OK
A24: 13 | F24: =C24*BattCellMaxV -> 0 | H24: =F24*B24*BattCellCapacity*0.0036 -> 0 | J24: =IF(COUNTBLANK(A24:E24)=4,"",IF(COUNTBLANK(A24:E24)>0,IncompleteText,IF(OR(F24>120,H24>6),ErrorText,OKText))) | K24: 距离极耳距离 Distance to terminal | P24: mm | Q24: =IF(O23="极耳 Cell tabs","",IF(ISBLANK(O24),IncompleteText,IF(O24<10,OKText,ErrorText)))
A25: 14 | F25: =C25*BattCellMaxV -> 0 | H25: =F25*B25*BattCellCapacity*0.0036 -> 0 | J25: =IF(COUNTBLANK(A25:E25)=4,"",IF(COUNTBLANK(A25:E25)>0,IncompleteText,IF(OR(F25>120,H25>6),ErrorText,OKText))) | K25: 单个测点测量的电芯数量 Cells sensed per sensor | O25: 1 | P25: cells | Q25: =IF(ISBLANK(O25),IncompleteText,OKText) -> OK
A26: 15 | F26: =C26*BattCellMaxV -> 0 | H26: =F26*B26*BattCellCapacity*0.0036 -> 0 | J26: =IF(COUNTBLANK(A26:E26)=4,"",IF(COUNTBLANK(A26:E26)>0,IncompleteText,IF(OR(F26>120,H26>6),ErrorText,OKText))) | K26: 导热材料型号(如果有) Thermal contact material (if used) | O26: 卡夫特K-5207
A27: 16 | F27: =C27*BattCellMaxV -> 0 | H27: =F27*B27*BattCellCapacity*0.0036 -> 0 | J27: =IF(COUNTBLANK(A27:E27)=4,"",IF(COUNTBLANK(A27:E27)>0,IncompleteText,IF(OR(F27>120,H27>6),ErrorText,OKText))) | K27: 导热材料说明书链接 Thermal contact material datasheet | O27: 导热胶_温度传感器与电芯极耳粘接处 | Q27: =IF(ISBLANK($O$26),"",IF(ISBLANK(O27),IncompleteText,OKText)) -> OK
A28: 17 | F28: =C28*BattCellMaxV -> 0 | H28: =F28*B28*BattCellCapacity*0.0036 -> 0 | J28: =IF(COUNTBLANK(A28:E28)=4,"",IF(COUNTBLANK(A28:E28)>0,IncompleteText,IF(OR(F28>120,H28>6),ErrorText,OKText))) | K28: 导热材料热导率 Thermal contact material conductivity | O28: 2.5 ± 0.5 | P28: W/(m∙K) | Q28: =IF(ISBLANK($O$26),"",IF(ISBLANK(O28),IncompleteText,OKText)) -> OK
A29: 18 | F29: =C29*BattCellMaxV -> 0 | H29: =F29*B29*BattCellCapacity*0.0036 -> 0 | J29: =IF(COUNTBLANK(A29:E29)=4,"",IF(COUNTBLANK(A29:E29)>0,IncompleteText,IF(OR(F29>120,H29>6),ErrorText,OKText))) | K29: 导热材料厚度 Thermal contact material thickness | O29: 0.4 | P29: mm | Q29: =IF(ISBLANK($O$26),"",IF(ISBLANK(O29),IncompleteText,OKText)) -> OK
K30: 温度测量覆盖率 Precentage of cells sensed | O30: =SUMIF(J12:J29,"=OK",D12:D29)*CellsPerTempSensor/TotalCells*100 -> 38.095238 | P30: % | Q30: =IF(ISERROR(O30),IncompleteText,IF(O30<20,ErrorText,OKText)) -> OK
A33: 维护插头示意图/照片 Pictures of Maintenance Plugs | J33: 极耳连接以及电芯固定示意图/照片 Picture of Cell Connections | S33: 温度传感器布置图 Picture of Temperature Sensor Location | AB33: 主保险丝和AIR和电芯分隔 Picture of Fuse and AIR Separation from cells | AK33: 电芯与电池箱内壁的绝缘 Picture of Segment Insulation between Cell Terminal and Sides of Accumulator Container | AT33: 模组上方绝缘 Picture of Insulation on Top of Segment
A52: 维护插头示意图/照片 Pictures of Maintenance Plugs | H52: =IF(COUNTIF(H53:H56,"="&IncompleteText),IncompleteText,IF(COUNTIF(H53:H56,"="&ErrorText),ErrorText,OKText)) -> OK | J52: 极耳连接以及电芯固定示意图/照片 Picture of Cell Connections | Q52: =IF(COUNTIF(Q53:Q55,"="&IncompleteText),IncompleteText,IF(COUNTIF(Q53:Q55,"="&ErrorText),ErrorText,OKText)) -> OK | S52: 温度传感器布置图 Picture of Temperature Sensor Location | Z52: =IF(COUNTIF(Z53:Z54,"="&IncompleteText),IncompleteText,IF(COUNTIF(Z53:Z54,"="&ErrorText),ErrorText,OKText)) -> OK | AB52: 主保险丝和AIR和电芯分隔 Picture of Fuse and AIR Separation from cells | AI52: =IF(COUNTIF(AI53,"="&IncompleteText),IncompleteText,IF(COUNTIF(AI53,"="&ErrorText),ErrorText,OKText)) -> OK | AK52: 模组绝缘 Segment Insulation | AR52: =IF(COUNTIF(AR53,"="&IncompleteText),IncompleteText,IF(COUNTIF(AR53,"="&ErrorText),ErrorText,OKText)) -> OK | AT52: 模组上方绝缘 Insulation on Top of Segment | BA52: =IF(COUNTIF(BA53,"="&IncompleteText),IncompleteText,IF(COUNTIF(BA53,"="&ErrorText),ErrorText,OKText)) -> OK
A53: 防止误插 Unique configurations of plugs | G53: TRUE | H53: =IF(ISBLANK(G53),IncompleteText,IF(G53,OKText,ErrorText)) -> OK | J53: 如果极耳采用紧固件压接，紧固件防松 Positive locking if bolted connections | P53: TRUE | Q53: =IF(ISBLANK(P53),IncompleteText,IF(P53,OKText,ErrorText)) -> OK | S53: 温度传感器直接接触极耳或者总线 Sensor in direct contact with terminal or busbar | Y53: TRUE | Z53: =IF(ISBLANK(Y53),IncompleteText,IF(Y53,OKText,ErrorText)) -> OK | AB53: 主保险丝和AIR和电芯分隔 Fuse and AIR Separation from cells | AH53: TRUE | AI53: =IF(ISBLANK(AH53),IncompleteText,IF(AH53,OKText,ErrorText)) -> OK | AK53: 电芯和电池箱内部绝缘 Insulation between cells and accumulator | AQ53: TRUE | AR53: =IF(ISBLANK(AQ53),IncompleteText,IF(AQ53,OKText,ErrorText)) -> OK | AT53: 模组上方绝缘 Insulation on Top of Segment | AZ53: TRUE | BA53: =IF(ISBLANK(AZ53),IncompleteText,IF(AZ53,OKText,ErrorText)) -> OK
A54: 非载流面绝缘 Non-conductive on un-necessary surface | G54: TRUE | H54: =IF(ISBLANK(G54),IncompleteText,IF(G54,OKText,ErrorText)) -> OK | J54: 极耳不受机械负载 No mechanic load on cell tabs | P54: TRUE | Q54: =IF(ISBLANK(P54),IncompleteText,IF(P54,OKText,ErrorText)) -> OK | S54: 未直接接触但足够近 Distance from sensor to cell negative terminal sufficienly close | Y54: TRUE | Z54: =IF(ISBLANK(Y54),IncompleteText,IF(Y54,OKText,ErrorText)) -> OK | AB54: 补充说明 Additional Comments | AI54: 规则参考 Rules Ref | AK54: 补充说明 Additional Comments | AR54: 规则参考 Rules Ref | AT54: 补充说明 Additional Comments | BA54: 规则参考 Rules Ref
A55: 安装不需要拆除电池箱部件 Accessible without additional desassembly | G55: TRUE | H55: =IF(ISBLANK(G55),IncompleteText,IF(G55,OKText,ErrorText)) -> OK | J55: 电芯在各个方向有限位，且受力面没有过小 Positions limits on all directions, sufficient surface with load | P55: TRUE | Q55: =IF(ISBLANK(P55),IncompleteText,IF(P55,OKText,ErrorText)) -> OK | S55: 补充说明 Additional Comments | Z55: 规则参考 Rules Ref | AB55: 主保险丝及AIR与电芯模组、金属电池箱之间不以空气作为绝缘。其朝向电芯模组和金属箱体的暴露表面采用K25-30G聚酰亚胺绝缘胶带连续包覆，单层厚度0.055 mm，实际不少于3层，总厚度不小于0.165 mm；外侧另设置连续的Formex GK-17BK绝缘阻燃隔离层。上述材料覆盖可能接近电芯模组或金属箱体的带电端子及导电表面，并通过结构固定防止移位，使主保险丝和AIR与电池箱其余部分之间形成实体绝缘阻燃隔离。ABS结构件仅作为机械支撑和附加防护，不作为主要阻燃证明依据。 | AI55: EV 5.5.14 | AK55: 每个电芯模组采用独立的刚性壳体进行机械隔离，模组壳体与金属隔板及电池箱体之间设置连续的Formex GK-17BK绝缘阻燃层。相邻模组之间由模组壳体、箱内隔板及Formex绝缘层形成实体隔离，绝缘结构覆盖可能接近电芯极耳、连接片及其他带电部件的位置，不以空气间隙作为唯一绝缘，从而防止模组之间以及模组与金属箱体之间发生短路或电弧。 | AR55: EV 5.4.6 | AT55: 各模组顶部设置与模组壳体螺栓固定的刚性盖板，盖板下方连续铺设Formex GK-17BK绝缘阻燃层。顶部盖板及Formex绝缘层完整覆盖电芯极耳、连接片和其他可能裸露的带电部位，装配后不存在可使掉落零件或工具直接接触带电导体的开口，从而防止维护过程中因零件或工具掉落造成模组内部短路或意外电弧。 | BA55: EV 5.4.6
A56: 主动锁紧/防松 Postive locking | G56: TRUE | H56: =IF(ISBLANK(G56),IncompleteText,IF(G56,OKText,ErrorText)) -> OK | J56: 电芯受力面应当占该表面的80% Surface with load: >= 80% | P56: TRUE | Q56: Recommended
A57: 补充说明 Additional Comments | H57: 规则参考 Rules Ref | J57: 补充说明 Additional Comments | Q57: 规则参考 Rules Ref | S57: 温度传感器布置在能够代表电芯最高温度的负极极耳激光焊接区域，并沿大电流路径直接粘接在极耳焊接表面，同时避开与母线直接接触的端子位置。传感器采用卡夫特K-5207导热绝缘胶固定，装配后胶层厚度约0.4 mm，可形成稳定的直接热接触并防止传感器因振动发生位移。该导热胶导热系数为2.5±0.5 W/(m·K)、体积电阻率为1.0×10¹⁴ Ω·cm、击穿强度不低于15 kV/mm、阻燃等级为UL94 V-0。按0.4 mm胶层计算的理论耐压约为6 kV，高于车辆365.4 V最大TS电压。 | Z57: EV 5.8.4
A58: 维护插头采用带机械防错键位和主动锁扣的绝缘连接器，分别设置在模组串联连接位置。通过模组壳体限位结构、插接方向及高压线束长度限制实现唯一匹配，避免不同位置的插头交叉误插。插头非载流表面均由绝缘壳体覆盖；电池箱开盖后，无需拆除模组或其他电池箱部件即可徒手拆装。插头完全插合后由机械锁扣主动锁紧，插合和断开状态可目视确认。移除维护插头后，电池箱内部模组串联回路及串联首、末端均实现电气分离。 | H58: EV 5.4.4 - EV 5.4.5 | J58: 电芯极耳采用激光焊接与连接片形成永久性导电连接，不采用极耳螺栓压紧连接。蓝色刚性焊接支撑板以及模组端部、侧面和底部限位结构共同承受机械载荷，并限制电芯在纵向、侧向及垂直方向的移动；极耳仅用于导电，不作为结构承载件，且不会被压入电芯本体。每个软包电芯之间均设置刚性支撑板，不属于无刚性隔板分隔的直接堆叠结构。 | Q58: EV 5.5.10 - EV 5.5.12
A64: 电池箱高压指示器原理图 Accumulator HV indicator | J64: 备用电芯(含供电检检查等)存放容器，若没有备用电芯则忽略本条 Storage container for spare battery cells (including provisions for inspection, etc.); if no spare cells are present, disregard this item.
A83: 电池箱高压指示器原理图 Accumulator HV indicator | H83: =IF(COUNTIF(H84:H92,"="&IncompleteText),IncompleteText,IF(COUNTIF(H84:H92,"="&ErrorText),ErrorText,OKText)) -> OK | J83: 备用电芯存放容器 Spare Battery Storage Container | Q83: =IF(P84="否 No",OKText,IF(COUNTIF(Q85:Q87,"="&IncompleteText),IncompleteText,IF(COUNTIF(Q85:Q87,"="&ErrorText),ErrorText,OKText))) -> OK
A84: 高压指示器来源 Indicator source | G84: 供应商采购 From suppliers | H84: =IF(ISBLANK(G84),IncompleteText,OKText) -> OK | J84: 是否有备用电芯（含用于电检检查的电芯）Whether there are spare cells (including cells used for electrical inspection) | P84: 否 No | Q84: =IF(ISBLANK(P84),IncompleteText,OKText) -> OK
A85: 电压传感器绝缘电压 Galvanic Isolation (Vdc) | G85: 2000Vdc | H85: =IF(G$84="车队自制电路 Self-designed",OKText,IF(ISBLANK(G85),IncompleteText,IF(G85>MaxTSVoltage,OKText,ErrorText))) -> OK | J85: 备用电芯必须存放在阻燃容器中 Spare cells must be stored in a fire retardant container | P85: TRUE | Q85: =IF(ISBLANK(P85),IncompleteText,IF(P85,OKText,ErrorText)) -> OK
...

Sheet 备用电池箱 Spare Accumulator
A1: 状态 Status | B1: =IF(N1="否 No",OKText,IF(SUM(COUNTIF(INDIRECT({"$E$3","$G$17","$G$18","$G$19","$J$22","$Q$22","$W$22","$AD$22","$AK$22","$Z$66","$Q$66","$H$66","$AI$66","$AR$66","$BA$66","$Q$97","$H$97"}),"="&IncompleteText)),IncompleteText,IF(SUM(COUNTIF(INDIRECT({"$E$3","$G$17","$G$18","$G$19","$J$22","$Q$22","$W$22","$AD$22","$AK$22","$Z$66","$Q$66","$H$66","$AI$66","$AR$66","$BA$66","$Q$97","$H$97"}),"="&ErrorText)),ErrorText,OKText))) -> OK | I1: 是否有备用电池箱 Whether exist spare accumulator | N1: 否 No
A3: 电芯单体 Battery Cell | E3: =IF(COUNTBLANK(C4:C14)>0,IncompleteText,OKText) -> BLANK
A4: 制造商 Make | I4: 说明：如果没有备用电池箱或备用电池箱采用完全相同的设计，此页可忽略 Note: If there is no spare accumulator or the spare accumulator has the same design, this page can be ignored.
A5: 型号 Model
A6: 额定容量 Nominal Capacity | D6: Ahr
A7: 最大电压 Maximum Voltage | D7: V
A8: 额定电压 Nominal Voltage | D8: V
A9: 最小电压 Minimum Voltage | D9: V
A10: 最大瞬时输出电流 Max output current | D10: A
A11: 最大连续输出电流 Max continous current | D11: A
A12: 最大工作温度 Max Cell temp | D12: C
A13: 电芯化学类型 Cell Chemistry
A14: 说明书超链接 Link to Datasheet
A17: 模组连接关系 Segment-to-Segment Connection | G17: =IF(ISBLANK(E17),IncompleteText,OKText) -> BLANK
A18: 驱动系统最大电压 Max TS voltage | E18: =IF(E17="串联 Serial",SUM(C26:C43)*BattCellMaxV_BK,C26*BattCellMaxV_BK*SUM(IF(FREQUENCY(E26:E43,E26:E43)>0,1))) -> 0 | F18: V | G18: =IF(MaxTSVoltage=0,IncompleteText,IF(E18>600,ErrorText,OKText)) -> OK
A19: 驱动系统额定电压 Nominal TS voltage | E19: =IF(E17="串联 Serial",SUM(C26:C43)*BattCellNomV_BK,C26*BattCellNomV_BK*SUM(IF(FREQUENCY(E26:E43,E26:E43)>0,1))) -> 0 | F19: V | G19: =IF(MaxTSVoltage=0,IncompleteText,IF(E19>600,ErrorText,OKText)) -> OK
A20: 电池单体数量 Total cells | E20: =SUMPRODUCT(B26:B43,C26:C43) -> 0
A22: 模组数据 Segement data | J22: =IF(COUNTIF(J23:J43,"="&IncompleteText),IncompleteText,IF(COUNTIF(J23:J43,"="&ErrorText),ErrorText,OKText)) -> BLANK | K22: BMS | Q22: =IF(COUNTIF(Q23:Q44,"="&IncompleteText),IncompleteText,IF(COUNTIF(Q23:Q44,"="&ErrorText),ErrorText,OKText)) -> BLANK | R22: 维护插头 Maintenance Plugs | W22: =IF(COUNTIF(W23:W35,"="&IncompleteText),IncompleteText,IF(COUNTIF(W23:W35,"="&ErrorText),ErrorText,OKText)) -> BLANK | X22: 绝缘材料 Insulating Materials | AD22: =IF(COUNTIF(AD23:AD32,"="&IncompleteText),IncompleteText,IF(COUNTIF(AD23:AD32,"="&ErrorText),ErrorText,OKText)) -> BLANK | AE22: [全车]自制PCB高低压隔离 High and low voltage isolation in [all] PCBs | AK22: =IF(AI23="否 No",OKText,IF(COUNTIF(AK23:AK27,"="&IncompleteText),IncompleteText,IF(COUNTIF(AK23:AK27,"="&ErrorText),ErrorText,OKText))) -> BLANK | AM22: [全车]自制PCB高低压隔离 High and low voltage isolation in [all] PCBs | AU22: 补充说明 Additional Comments
A23: 电芯串并关系 Cell connection order | J23: =IF(ISBLANK(D23),IncompleteText,OKText) -> BLANK | K23: BMS拓扑 BMS Type | Q23: =IF(ISBLANK(O23),IncompleteText,OKText) -> BLANK | R23: 接插件/连接器 Connector | W23: =IF(ISBLANK(U23),IncompleteText,OKText) -> BLANK | X23: 电芯及电池箱内壁之间绝缘材料 Between cells and accumulator | AD23: =IF(ISBLANK(AB23),IncompleteText,OKText) -> BLANK | AE23: 全车是否有自制同时带高压和低压的PCB Does the entire vehicle contain any custom-made PCBs that handle both TS&LVS? | AK23: =IF(ISBLANK(AI23),IncompleteText,OKText) -> BLANK | AM23: 展示所有同时包含高低压的PCB的爬电距离和电气间隙，若整车自制PCB没有同时存在TS&LVS，则忽略本条 Displays creepage and clearance distances for all PCBs containing both TS and LVS | AU23: Fill upon request 需要时填写
A24: 模组编号 Segement | B24: 并联数 Parallel cells | C24: 串联数 Serial cells | D24: 温度测点数量 Temp sensors | E24: 电池箱编号 Accumulator number | F24: 模组最大电压 Max Voltage[V] | H24: 模组能量 Segement energy [MJ] | K24: BMS来源 BMS source | Q24: =IF(ISBLANK(O24),IncompleteText,OKText) -> BLANK | R24: 额定电流 Ampacity | U24: =VLOOKUP(U23,ConnectorTable,3,FALSE) -> #N/A | V24: A | W24: =IF(ISERROR(U24),IncompleteText,IF(E17="串联 Serial",IF(U24>=U34,OKText,ErrorText),IF(E17="并联 Parallel",IF(U24>=U26,OKText,ErrorText),IncompleteText))) -> BLANK | X24: 电压等级 Voltage Rating | AB24: =VLOOKUP(AB23,InsulationsTable,4,FALSE) -> #N/A | AC24: V | AD24: =IF(ISERROR(AB24),IncompleteText,IF(AB24<MaxTSVoltage,ErrorText,OKText)) -> BLANK | AE24: 驱动系统电压范围 Drive system voltage range | AK24: =IF(ISBLANK(AI24),IncompleteText,OKText) -> BLANK
K25: 制造商 Vendor | N25: 型号 Type | Q25: =IF(O24="供应商提供 From Suppliers",IF(OR(ISBLANK(L25),ISBLANK(O25)),IncompleteText,OKText),"") | R25: 对应保险丝 Fuse provides protections | W25: =IF(E17="串联 Serial","",IF(ISBLANK(U25),IncompleteText,OKText)) -> BLANK | X25: 温度等级 Temperature Rating | AB25: =VLOOKUP(AB23,InsulationsTable,5,FALSE) -> #N/A | AC25: C | AD25: =IF(ISERROR(AB25),IncompleteText,IF(AB25<90,ErrorText,OKText)) -> BLANK | AE25: 爬电距离计算值 Calculated creepage distance | AJ25: mm | AK25: =IF(ISBLANK(AI25),IncompleteText,OKText) -> BLANK
A26: 1 | F26: =C26*BattCellMaxV_BK -> 0 | H26: =F26*B26*BattCellCapacity_BK*0.0036 -> 0 | J26: =IF(COUNTBLANK(A26:E26)>0,IncompleteText,IF(OR(F26>120,H26>6),ErrorText,OKText)) -> BLANK | K26: 驱动系统到低压控制系统绝缘电压 Galvanic Isolation TS to LVS | P26: V | Q26: =IF(ISBLANK(O26),IncompleteText,IF(O26<E18,ErrorText,OKText)) -> BLANK | R26: 保险丝额定电流 Fuse ampacity | U26: =VLOOKUP(U25,FuseTable,3,FALSE) -> #N/A | V26: A | X26: 电芯上方覆盖 On top of cells | AD26: =IF(ISBLANK(AB26),IncompleteText,OKText) -> BLANK | AE26: 电气间隙计算值 Calculated electrical clearance | AJ26: mm | AK26: =IF(ISBLANK(AI26),IncompleteText,OKText) -> BLANK
A27: 2 | F27: =C27*BattCellMaxV_BK -> 0 | H27: =F27*B27*BattCellCapacity_BK*0.0036 -> 0 | J27: =IF(COUNTBLANK(A27:E27)=4,"",IF(COUNTBLANK(A27:E27)>0,IncompleteText,IF(OR(F27>120,H27>6),ErrorText,OKText))) | K27: 模组间绝缘电压 Galvanic Isolation between segments | P27: V | Q27: =IF(ISBLANK(O27),IncompleteText,IF(O27<MAX(F26:G43),ErrorText,OKText)) -> BLANK | R27: AIR | X27: 电压等级 Voltage Rating | AB27: =VLOOKUP(AB26,InsulationsTable,4,FALSE) -> #N/A | AC27: V | AD27: =IF(ISERROR(AB27),IncompleteText,IF(AB27<MaxTSVoltage,ErrorText,OKText)) -> BLANK | AE27: 是否三防胶覆盖 If covered with conformal coating | AK27: =IF(ISBLANK(AI27),IncompleteText,OKText) -> BLANK
A28: 3 | F28: =C28*BattCellMaxV_BK -> 0 | H28: =F28*B28*BattCellCapacity_BK*0.0036 -> 0 | J28: =IF(COUNTBLANK(A28:E28)=4,"",IF(COUNTBLANK(A28:E28)>0,IncompleteText,IF(OR(F28>120,H28>6),ErrorText,OKText))) | K28: 隔离器件 Galvanic Isolation devices | Q28: =IF($O$24="车队自制 Team design",IF(ISBLANK(O28),IncompleteText,OKText),"") | R28: 型号 Make/Model | W28: =IF(ISBLANK(U28),IncompleteText,OKText) -> BLANK | X28: 温度等级 Temperature Rating | AB28: =VLOOKUP(AB26,InsulationsTable,5,FALSE) -> #N/A | AC28: C | AD28: =IF(ISERROR(AB28),IncompleteText,IF(AB28<90,ErrorText,OKText)) -> BLANK
A29: 4 | F29: =C29*BattCellMaxV_BK -> 0 | H29: =F29*B29*BattCellCapacity_BK*0.0036 -> 0 | J29: =IF(COUNTBLANK(A29:E29)=4,"",IF(COUNTBLANK(A29:E29)>0,IncompleteText,IF(OR(F29>120,H29>6),ErrorText,OKText))) | K29: 隔离器件说明书 Galvanic Isolation devices datasheets | Q29: =IF($O$24="车队自制 Team design",IF(ISBLANK(O29),IncompleteText,OKText),"") | R29: 触点额定电压 Contactnoimal volatge | U29: =VLOOKUP(U28,ContactorsTable,2,FALSE) -> #N/A | V29: Vdc | W29: =IF(ISERROR(U29),IncompleteText,IF(U29<MaxTSVoltage,ErrorText,OKText)) -> BLANK | X29: AIR,主保险丝与电芯之间 Between AIRs and Cells | AD29: =IF(ISBLANK(AB29),IncompleteText,OKText) -> BLANK
A30: 5 | F30: =C30*BattCellMaxV_BK -> 0 | H30: =F30*B30*BattCellCapacity_BK*0.0036 -> 0 | J30: =IF(COUNTBLANK(A30:E30)=4,"",IF(COUNTBLANK(A30:E30)>0,IncompleteText,IF(OR(F30>120,H30>6),ErrorText,OKText))) | K30: 电芯电压测量 Voltage Sense Leads | R30: 最大分断电流 Max switching current | U30: =VLOOKUP(U28,ContactorsTable,4,FALSE) -> #N/A | V30: A | X30: 电压等级 Voltage Rating | AB30: =VLOOKUP(AB29,InsulationsTable,4,FALSE) -> #N/A | AC30: V | AD30: =IF(ISERROR(AB30),IncompleteText,IF(AB30<MaxTSVoltage,ErrorText,OKText)) -> BLANK
A31: 6 | F31: =C31*BattCellMaxV_BK -> 0 | H31: =F31*B31*BattCellCapacity_BK*0.0036 -> 0 | J31: =IF(COUNTBLANK(A31:E31)=4,"",IF(COUNTBLANK(A31:E31)>0,IncompleteText,IF(OR(F31>120,H31>6),ErrorText,OKText))) | K31: 最长采样线线缆长度 Max lead length | P31: cm | Q31: =IF(ISBLANK(O31),IncompleteText,OKText) -> BLANK | R31: 额定电流 Max continuous current | U31: =VLOOKUP(U28,ContactorsTable,3,FALSE) -> #N/A | V31: A | W31: =IF(ISERROR(U31),IncompleteText,IF(U31>=U34,OKText,ErrorText)) -> BLANK | X31: 温度等级 Temperature Rating | AB31: =VLOOKUP(AB29,InsulationsTable,5,FALSE) -> #N/A | AC31: C | AD31: =IF(ISERROR(AB31),IncompleteText,IF(AB31<90,ErrorText,OKText)) -> BLANK
A32: 7 | F32: =C32*BattCellMaxV_BK -> 0 | H32: =F32*B32*BattCellCapacity_BK*0.0036 -> 0 | J32: =IF(COUNTBLANK(A32:E32)=4,"",IF(COUNTBLANK(A32:E32)>0,IncompleteText,IF(OR(F32>120,H32>6),ErrorText,OKText))) | K32: 采样线过流保护器件型号 Sense lead overprotection device | Q32: =IF(ISBLANK(O32),IncompleteText,OKText) -> BLANK | R32: 主保险丝 Main Fuse | X32: 防火等级 Flammability Rating | AB32: =VLOOKUP(AB29,InsulationsTable,6,FALSE) -> #N/A | AD32: =IF(ISNA(AB32),IncompleteText,OKText) -> BLANK
A33: 8 | F33: =C33*BattCellMaxV_BK -> 0 | H33: =F33*B33*BattCellCapacity_BK*0.0036 -> 0 | J33: =IF(COUNTBLANK(A33:E33)=4,"",IF(COUNTBLANK(A33:E33)>0,IncompleteText,IF(OR(F33>120,H33>6),ErrorText,OKText))) | K33: 过流保护器件位置 Overcurrent protection device location | Q33: =IF(ISBLANK(O33),IncompleteText,OKText) -> BLANK | R33: 主保险丝 Main Fuse | W33: =IF(ISBLANK(U33),IncompleteText,OKText) -> BLANK
A34: 9 | F34: =C34*BattCellMaxV_BK -> 0 | H34: =F34*B34*BattCellCapacity_BK*0.0036 -> 0 | J34: =IF(COUNTBLANK(A34:E34)=4,"",IF(COUNTBLANK(A34:E34)>0,IncompleteText,IF(OR(F34>120,H34>6),ErrorText,OKText))) | K34: 其他位置说明 | Q34: =IF(O33="其他 Other",IF(ISBLANK(O34),IncompleteText,OKText),"") | R34: 额定电流 Max fuse ampacity | U34: =VLOOKUP(U33,FuseTable,3,FALSE) -> #N/A | V34: A
A35: 10 | F35: =C35*BattCellMaxV_BK -> 0 | H35: =F35*B35*BattCellCapacity_BK*0.0036 -> 0 | J35: =IF(COUNTBLANK(A35:E35)=4,"",IF(COUNTBLANK(A35:E35)>0,IncompleteText,IF(OR(F35>120,H35>6),ErrorText,OKText))) | K35: 过流保护电压等级 Overcurrent voltage rating | O35: =VLOOKUP(O32,FuseTable,2,FALSE) -> #N/A | Q35: =IF(ISERROR(O35),IncompleteText,IF(AND(O35<MAX(F26:G43),O23="集中式 Centralized"),ErrorText,OKText)) -> BLANK | R35: 额定电压 Main fuse voltage | U35: =VLOOKUP(U33,FuseTable,2,FALSE) -> #N/A | V35: V | W35: =IF(U35<MaxTSVoltage,ErrorText,OKText) -> #N/A
A36: 11 | F36: =C36*BattCellMaxV_BK -> 0 | H36: =F36*B36*BattCellCapacity_BK*0.0036 -> 0 | J36: =IF(COUNTBLANK(A36:E36)=4,"",IF(COUNTBLANK(A36:E36)>0,IncompleteText,IF(OR(F36>120,H36>6),ErrorText,OKText))) | K36: 温度传感器
A37: 12 | F37: =C37*BattCellMaxV_BK -> 0 | H37: =F37*B37*BattCellCapacity_BK*0.0036 -> 0 | J37: =IF(COUNTBLANK(A37:E37)=4,"",IF(COUNTBLANK(A37:E37)>0,IncompleteText,IF(OR(F37>120,H37>6),ErrorText,OKText))) | K37: 温度传感器位置 Temp sensor location | Q37: =IF(ISBLANK(O37),IncompleteText,OKText) -> BLANK
A38: 13 | F38: =C38*BattCellMaxV_BK -> 0 | H38: =F38*B38*BattCellCapacity_BK*0.0036 -> 0 | J38: =IF(COUNTBLANK(A38:E38)=4,"",IF(COUNTBLANK(A38:E38)>0,IncompleteText,IF(OR(F38>120,H38>6),ErrorText,OKText))) | K38: 距离极耳距离 Distance to terminal | P38: mm | Q38: =IF(O37="极耳 Cell tabs","",IF(ISBLANK(O38),IncompleteText,IF(O38<10,OKText,ErrorText))) -> BLANK
A39: 14 | F39: =C39*BattCellMaxV_BK -> 0 | H39: =F39*B39*BattCellCapacity_BK*0.0036 -> 0 | J39: =IF(COUNTBLANK(A39:E39)=4,"",IF(COUNTBLANK(A39:E39)>0,IncompleteText,IF(OR(F39>120,H39>6),ErrorText,OKText))) | K39: 单个测点测量的电芯数量 Cells sensed per sensor | P39: cells | Q39: =IF(ISBLANK(O39),IncompleteText,OKText) -> BLANK
A40: 15 | F40: =C40*BattCellMaxV_BK -> 0 | H40: =F40*B40*BattCellCapacity_BK*0.0036 -> 0 | J40: =IF(COUNTBLANK(A40:E40)=4,"",IF(COUNTBLANK(A40:E40)>0,IncompleteText,IF(OR(F40>120,H40>6),ErrorText,OKText))) | K40: 导热材料型号(如果有) Thermal contact material (if used)
A41: 16 | F41: =C41*BattCellMaxV_BK -> 0 | H41: =F41*B41*BattCellCapacity_BK*0.0036 -> 0 | J41: =IF(COUNTBLANK(A41:E41)=4,"",IF(COUNTBLANK(A41:E41)>0,IncompleteText,IF(OR(F41>120,H41>6),ErrorText,OKText))) | K41: 导热材料说明书链接 Thermal contact material datasheet | Q41: =IF(ISBLANK($O$40),"",IF(ISBLANK(O41),IncompleteText,OKText))
A42: 17 | F42: =C42*BattCellMaxV_BK -> 0 | H42: =F42*B42*BattCellCapacity_BK*0.0036 -> 0 | J42: =IF(COUNTBLANK(A42:E42)=4,"",IF(COUNTBLANK(A42:E42)>0,IncompleteText,IF(OR(F42>120,H42>6),ErrorText,OKText))) | K42: 导热材料热导率 Thermal contact material conductivity | P42: W/(m∙K) | Q42: =IF(ISBLANK($O$40),"",IF(ISBLANK(O42),IncompleteText,OKText))
A43: 18 | F43: =C43*BattCellMaxV_BK -> 0 | H43: =F43*B43*BattCellCapacity_BK*0.0036 -> 0 | J43: =IF(COUNTBLANK(A43:E43)=4,"",IF(COUNTBLANK(A43:E43)>0,IncompleteText,IF(OR(F43>120,H43>6),ErrorText,OKText))) | K43: 导热材料厚度 Thermal contact material thickness | P43: mm | Q43: =IF(ISBLANK($O$40),"",IF(ISBLANK(O43),IncompleteText,OKText))
K44: 温度测量覆盖率 Precentage of cells sensed | O44: =SUMIF(J26:J43,"=OK",D26:D43)*CellsPerTempSensor_BK/TotalCells_BK*100 -> #DIV/0! | P44: % | Q44: =IF(ISERROR(O44),IncompleteText,IF(O44<20,ErrorText,OKText)) -> BLANK
...

Sheet 预充电放电 PrechargeDischarge
A1: 状态 Status | B1: {=IF(SUM(COUNTIF(INDIRECT({"$F$2","$L$2","$R$2"}),"="&IncompleteText)),IncompleteText,IF(SUM(COUNTIF(INDIRECT({"$F$2","$L$2","$R$2"}),"="&ErrorText)),ErrorText,OKText))} -> OK
A2: 预充电回路 Precharge | F2: =IF(COUNTIF(F3:F19,"="&IncompleteText),IncompleteText,IF(COUNTIF(F3:F19,"="&ErrorText),ErrorText,OKText)) -> OK | G2: 放电回路 Discharge | L2: =IF(COUNTIF(L3:L15,"="&IncompleteText),IncompleteText,IF(COUNTIF(L3:L15,"="&ErrorText),ErrorText,OKText)) -> OK | M2: 驱动系统测量点 TSMP | R2: =IF(COUNTIF(R3:R8,"="&IncompleteText),IncompleteText,IF(COUNTIF(R3:R8,"="&ErrorText),ErrorText,OKText)) -> OK | S2: 规则参考 Rules ref
A3: 电阻型号 Resistor Type | D3: RXG24 75w 3000Ω-J | F3: =IF(ISBLANK(D3),IncompleteText,OKText) -> OK | G3: 电阻型号 Resistor Type | J3: RXG24-100W-2000Ω-J | L3: =IF(ISBLANK(J3),IncompleteText,OKText) -> OK | M3: 电阻型号 Resistor Type | P3: RX24-50W-10KΩ-J | R3: =IF(ISBLANK(P3),IncompleteText,OKText) -> OK | S3: EV 5.7 EV 4.9 EV 4.7
A4: 并联数 # parallel | D4: 1 | F4: =IF(ISBLANK(D4),IncompleteText,OKText) -> OK | G4: 并联数 # parallel | J4: 1 | L4: =IF(ISBLANK(J4),IncompleteText,OKText) -> OK | M4: 并联数 # parallel | P4: 1 | R4: =IF(ISBLANK(P4),IncompleteText,OKText) -> OK
A5: 串联数 # serial | D5: 1 | F5: =IF(ISBLANK(D5),IncompleteText,OKText) -> OK | G5: 串联数 # serial | J5: 1 | L5: =IF(ISBLANK(J5),IncompleteText,OKText) -> OK | M5: 串联数 # serial | P5: 1 | R5: =IF(ISBLANK(P5),IncompleteText,OKText) -> OK
A6: 总阻值 Resistance | D6: =VLOOKUP(D3,ResistorsTable,3,)*D5/D4 -> 3000 | E6: Ohms | G6: 总阻值 Resistance | J6: =VLOOKUP(J3,ResistorsTable,3,)*J5/J4 -> 2000 | K6: Ohms | M6: 总阻值 Resistance | P6: =VLOOKUP(P3,ResistorsTable,3,)*P5/P4 -> 10000 | Q6: Ohms | R6: =IF(MaxTSVoltage<=200,IF(P6=5000,OKText,ErrorText),IF(MaxTSVoltage>400,IF(P6=15000,OKText,ErrorText),IF(P6=10000,OKText,ErrorText))) -> OK
A7: 额定功率 Cont power | D7: =VLOOKUP(D3,ResistorsTable,4,FALSE)*D4*D5 -> 75 | E7: W | G7: 额定功率 Cont power | J7: =VLOOKUP(J3,ResistorsTable,4,FALSE)*J4*J5 -> 100 | K7: W | L7: =IF(J7=0,IncompleteText,IF(J7>=J9,OKText,ErrorText)) -> OK | M7: 额定功率 Cont power | P7: =VLOOKUP(P3,ResistorsTable,4,FALSE)*P5*P4 -> 50 | Q7: W | R7: =IF(P7<P9,ErrorText,OKText) -> OK
A8: 瞬时持续功率(5s) Power @ 5s | D8: 0.887 | E8: W | F8: =IF(ISBLANK(D8),IncompleteText,OKText) -> OK | G8: 额定电压 Rated Voltage | J8: =VLOOKUP(J3,ResistorsTable,2,FALSE)*J5 -> 447.2 | K8: Vdc | L8: =IF(J8=0,IncompleteText,IF(J8<MaxTSVoltage,ErrorText,OKText)) -> OK | M8: 额定电压 Rated Voltage | P8: =VLOOKUP(P3,ResistorsTable,2,FALSE)*P5 -> 707.1 | Q8: V | R8: =IF(P8<MaxTSVoltage,ErrorText,OKText) -> OK
A9: 额定电压 Rated Voltage | D9: =VLOOKUP(D3,ResistorsTable,2,FALSE)*D5 -> 474.3 | E9: Vdc | F9: =IF(D9<MaxTSVoltage,ErrorText,OKText) -> OK | G9: 放电峰值功率 Peak Power | J9: =MaxTSVoltage^2/DischargeRes -> 66.75858 | K9: W | M9: 短路功率 Power if short circuit | P9: =MaxTSVoltage^2/(2*P6) -> 6.675858 | Q9: W | R9: =IF(ISNA(P9),IncompleteText,IF((P9/2)<=P7,OKText,ErrorText)) -> OK
A10: 总线电容 Bus Capacitance | D10: 0.8 | E10: mF | F10: =IF(ISBLANK(BusCap),IncompleteText,OKText) -> OK | G10: 放电峰值电流 Peak Current | J10: =MaxTSVoltage/DischargeRes -> 0.1827 | K10: A
A11: 充电截止条件 End of precharge | D11: 95 | E11: % | F11: =IF(ISBLANK(D11),IncompleteText,IF(D11>=95,OKText,ErrorText)) -> OK | G11: 放电时间 Discharge time | J11: =-LN(60/MaxTSVoltage)*DischargeRes*(BusCap/1000) -> 2.8906369 | K11: s
A12: 峰值功率 Peak Power | D12: =MaxTSVoltage^2/PrechargeRes -> 44.50572 | E12: W | G12: 放电继电器 Relay | J12: HVR1B12 | L12: =IF(ISBLANK(J12),IncompleteText,OKText) -> OK
A13: 峰值电流 Peak Current | D13: =MaxTSVoltage/PrechargeRes -> 0.1218 | E13: A | G13: 继电器触点额定电压 Contacts rated volatge | J13: =VLOOKUP(J12,ContactorsTable,2,FALSE) -> 1000 | K13: V | L13: =IF(J13<MaxTSVoltage,ErrorText,OKText) -> OK
A14: 充电到95% Time to 95% | D14: =-LN(0.05)*(BusCap/1000)*PrechargeRes -> 7.1897575 | E14: sec | G14: 继电器触点额定电流 Contact rated current | J14: =VLOOKUP(J12,ContactorsTable,3,FALSE) -> 1 | K14: A | L14: =IF(J14<J10,ErrorText,OKText) -> OK
A15: 预充电能量95% Energy on res to 95% | D15: =MaxTSVoltage^2*(BusCap/1000)/2*(1-EXP(-D14*2/(PrechargeRes*(BusCap/1000)))) -> 53.273347 | E15: J | G15: 继电器断电状态 Normal State | J15: =VLOOKUP(J12,ContactorsTable,5,FALSE) -> NC | L15: =IF(J15<>"NC",ErrorText,OKText) -> OK
A16: 平均功率 average power | D16: =D15/D14 -> 7.4096167 | E16: W
A17: 预充电继电器 Relay | D17: LEV50-12HD | F17: =IF(ISBLANK(D17),IncompleteText,OKText) -> OK
A18: 继电器触点额定电压 Contacts rated volatge | D18: =VLOOKUP(D17,ContactorsTable,2,FALSE) -> 900 | E18: Vdc | F18: =IF(D18<MaxTSVoltage,ErrorText,OKText) -> OK
A19: 继电器触点额定电流 Contact rated current | D19: =VLOOKUP(D17,ContactorsTable,3,FALSE) -> 50 | E19: A | F19: =IF(D19<D13,ErrorText,OKText) -> OK
A21: 补充说明 Additional Comments
A22: 预充电阻 RXG24 75W 3000Ω-J 按规格书具备 10 倍额定功率 5 s 的过载能力，即 750 W @ 5 s。本车预充峰值功率为 57.1 W，低于连续额定功率 75 W，并安装热阻 ≤ 3.0 ℃/W 的铝散热器。

Sheet 充电 Charging
A1: 状态 Status | B1: {=IF(SUM(COUNTIF(INDIRECT({"$F$2","$H$31","$Q$31","$Z$31"}),"="&IncompleteText)),IncompleteText,IF(SUM(COUNTIF(INDIRECT({"$F$2","$H$31","$Q$31","$Z$31"}),"="&ErrorText)),ErrorText,OKText))} -> OK
A2: 充电机 Charger | F2: =IF(COUNTIF(F3:F10,"="&IncompleteText),IncompleteText,IF(COUNTIF(F3:F10,"="&ErrorText),ErrorText,OKText)) -> OK | H2: 补充说明 Additioanl Comments
A3: 制造商 Make | D3: 长春浩泰科技有限公司 | F3: =IF(ISBLANK(D3),IncompleteText,OKText) -> OK | H3: 更新了充电驱动回路原理图
A4: 型号 Type | D4: EP-2308 3.3kW Charger | F4: =IF(ISBLANK(D4),IncompleteText,OKText) -> OK
A5: 说明书超链接 Datasheet link | D5: 3.3KW FSE Charger Specification 2022 | F5: =IF(ISBLANK(D5),IncompleteText,OKText) -> OK
A6: 输入电压(市电或工业电) Input Voltage | D6: 90-265 | E6: Vac | F6: =IF(ISBLANK(D6),IncompleteText,OKText) -> OK
A7: 输入电流 Input Current | D7: 16 | E7: A | F7: =IF(ISBLANK(D7),IncompleteText,OKText) -> OK
A8: 输出电压(定值或范围) Output Voltage | D8: 220~440V | E8: V | F8: =IF(ISBLANK(D8),IncompleteText,OKText) -> OK
A9: 输出电流 Output Current | D9: 10 | E9: A | F9: =IF(ISBLANK(D9),IncompleteText,OKText) -> OK
A10: 充电机额定功率 Rated Power | D10: 3.3 | E10: kW | F10: =IF(ISBLANK(D10),IncompleteText,OKText) -> OK
A12: 充电驱动系统回路 Charging Tractive System Schematic | J12: 充电安全回路 Charging Shutdown Circuit | S12: 电池箱小推车 Accumulator Handcart
A31: 充电驱动系统回路 Charging Tractive System Schematic | H31: =IF(COUNTIF(H33:H38,"="&IncompleteText),IncompleteText,IF(COUNTIF(H33:H38,"="&ErrorText),ErrorText,OKText)) -> OK | J31: 充电安全回路 Charging Shutdown Circuit | Q31: =IF(COUNTIF(Q33:Q38,"="&IncompleteText),IncompleteText,IF(COUNTIF(Q33:Q38,"="&ErrorText),ErrorText,OKText)) -> OK | S31: 电池箱小推车 Accumulator Handcart | Z31: =IF(COUNTIF(Z33:Z37,"="&IncompleteText),IncompleteText,IF(COUNTIF(Z33:Z37,"="&ErrorText),ErrorText,OKText)) -> OK
A32: 规则参考 Rules Ref | J32: 规则参考 Rules Ref | S32: 规则参考 Rules Ref
C33: 主保险丝（直流） Main Fuse on DC bus | G33: TRUE | H33: =IF(ISBLANK(G33),IncompleteText,IF(G33,OKText,ErrorText)) -> OK | L33: IMD控制的继电器 IMD Controlled powerstage | P33: TRUE | Q33: =IF(ISBLANK(P33),IncompleteText,IF(P33,OKText,ErrorText)) -> OK | S33: EV 8.4.7 | U33: 垂直防火墙及高度要求满足 Firewall Height and coverage | Y33: TRUE | Z33: =IF(ISBLANK(Y33),IncompleteText,IF(Y33,OKText,ErrorText)) -> OK
