Workbook
Name BattCellCapacity: '规格书 Datasheet'!$C$5
Name BattCellMaxV: '规格书 Datasheet'!$C$6
Name BattCellNomV: '规格书 Datasheet'!$C$7
Name BusCap: '预充电放电 PrechargeDischarge'!$D$10
Name CellsPerTempSensor: '电池箱 Accumulator'!$O$25
Name ConnectorNames: '规格书 Datasheet'!$B$74:$B$92
Name ConnectorsTable: '规格书 Datasheet'!$A$74:$H$92
Name ConnectorTable: '规格书 Datasheet'!$B$74:$H$92
Name ContactorNames: '规格书 Datasheet'!$B$66:$B$70
Name ContactorsTable: '规格书 Datasheet'!$B$66:$H$70
Name DischargeRes: '预充电放电 PrechargeDischarge'!$J$6
Name ErrorText: "WARNING"
Name FuseName: '规格书 Datasheet'!$B$42:$B$53
Name FuseNames: #REF!
Name FuseNoiCur: '电池箱 Accumulator'!$U$20
Name FusesTable: #REF!
Name FuseTable: '规格书 Datasheet'!$B$42:$H$53
Name IncompleteText: "BLANK"
Name InsulationNames: '规格书 Datasheet'!$B$96:$B$105
Name InsulationsTable: '规格书 Datasheet'!$B$96:$I$105
Name MaxTSVoltage: '电池箱 Accumulator'!$E$4
Name NominalTSVoltage: #REF!
Name OKText: "OK"
Name PrechargeRes: '预充电放电 PrechargeDischarge'!$D$6
Name ResistorsNames: '规格书 Datasheet'!$B$57:$B$62
Name ResistorsTable: '规格书 Datasheet'!$B$57:$H$62
Name TotalCells: '电池箱 Accumulator'!$E$6

Sheet 总览 Overview
A1: 文档填写要求 Document Filling Requirements | J1: 结果汇总 Status | M1: 最终结果 Overall Results
A2: - 所有橙色背景的单元格均需要填写 - 蓝色背景的单元格是自动生成的检查结果 - 图片必须放置在指定区域上并且高清且横纵比正常。图片需要能够被放大以进行进一步审核 - 所有要求规格书的都应该在规定位置提供下载超链接,优先放置供应商公开网址的信息,允许车队提供的网盘,但是分享链接应当是无密码且长期有效的。链接不必完整显示在文档中 - 禁止链接到淘宝产品介绍页面 - 额外补充信息仅在审核员特殊要求时填写 - 完成后删除所有的此单元格以外的样例(橙色图片)/说明性文字（斜体） - 由于反馈更改的内容必须要标为红色。未标红视为未更改。请仅标红当前最新更改部分 - 无论当前是否已经对ESF予以通过，任何未经许可的对自动检查表格模板的修改/破解将导致该车队本年度的电检资格取消。 - 自动检查通过并不代表ESF必然获得通过 ———— - All cells with an orange background need to be filled out - Cells with a blue background are automatically generated inspection results - Images must be clear and recognizable - All required specifications should provide download hyperlinks in the designated location. Preference should be given to publicly accessible URLs from suppliers. Cloud drives provided by the team are allowed, but the shared links should be password-free and long-term valid. The links do not need to be fully displayed in the document. - Linking to online vendor product introduction pages is prohibited。 - Additional comments should only be filled in upon special request from the auditor. - After completion, delete all examples (orange images)/explanatory text (italic) except for this cell. - Changes made due to feedback must be marked in red. Changes not marked in red will be considered unmodified. Please only mark the most recent changes in red. - Regardless of whether the ESF has currently been approved, any unauthorized modifications/hacks to the automated checklist template will result in the team's disqualification from the electrical inspection for the current year. - Passing the automated check does not guarantee that the ESF will be approved. | J2: 规格书 Datasheets | K2: ='规格书 Datasheet'!B1 -> BLANK | M2: =IF(COUNTIF(K2:K11,"="&IncompleteText),IncompleteText,IF(COUNTIF(K2:K11,"="&ErrorText),ErrorText,OKText)) -> BLANK
J3: 驱动系统原理图 TS Schematics | K3: ='驱动系统原理图 TS Schematics'!$B$1 -> BLANK
J4: 电池箱 Accumulator | K4: ='电池箱 Accumulator'!B1 -> BLANK
J5: 预充电/放电回路 Precharge/Discharge | K5: ='预充电放电 PrechargeDischarge'!B1 -> BLANK
J6: 充电系统 Charging | K6: ='充电 Charging'!B1 -> BLANK
J7: 安全系统 Shutdown circuits | K7: ='安全系统 Shutdown circuit'!B1 -> BLANK
J8: 扭矩输出 Torque security | K8: ='扭矩指令 Torque Security'!B1 -> BLANK
J9: 其他 Other | K9: ='其他 Others'!B1 -> BLANK
J10: 接地 Grounding | K10: ='接地 Grounding'!B1 -> BLANK
J11: 车队信息 Team info | K11: =O12 -> BLANK
J12: 车队信息 Team info | O12: =IF(COUNTIF(O13:O15,"="&IncompleteText),IncompleteText,IF(COUNTIF(O13:O15,"="&ErrorText),ErrorText,OKText)) -> BLANK
J13: 学校 University | O13: =IF(ISBLANK(K13),IncompleteText,OKText) -> BLANK
J14: 车队名称 Team | O14: =IF(ISBLANK(K14),IncompleteText,OKText) -> BLANK
J15: 车号 Car Number | O15: =IF(ISBLANK(K15),IncompleteText,OKText) -> BLANK
J17: 驱动系统最大电压 Max TS voltage | K17: =MaxTSVoltage -> 0 | L17: V
J18: 主保险丝额定电流 Accumulator | K18: ='电池箱 Accumulator'!U20 -> #N/A | L18: A
A20: Additional Comment - 1 | I20: Additional Comment - 2

Sheet 规格书 Datasheet
A1: 状态 Status | B1: {=IF(SUM(COUNTIF(INDIRECT({"$F$2","$I$15","$I$39","$I$54","$I$63","$I$71","$J$93"}),"="&IncompleteText))>0,IncompleteText,IF(SUM(COUNTIF(INDIRECT({"$F$2","$I$15","$I$39","$I$54","$I$63","$I$71","$J$93"}),"="&ErrorText))>0,ErrorText,OKText))} -> BLANK
A2: 电芯单体 Battery Cell | E2: =IF(COUNTBLANK(C3:C13)>0,IncompleteText,OKText) -> BLANK
A3: 制造商 Make
A4: 型号 Model
A5: 额定容量 Nominal Capacity | D5: Ahr
A6: 最大电压 Maximum Voltage | D6: V
A7: 额定电压 Nominal Voltage | D7: V
A8: 最小电压 Minimum Voltage | D8: V
A9: 最大瞬时输出电流 Max output current | D9: A
A10: 最大连续输出电流 Max continous current | D10: A
A11: 最大工作温度 Max Cell temp | D11: C
A12: 电芯化学类型 Cell Chemistry
A13: 说明书超链接 Link to Datasheet
A15: 导体信息 Conductors | I15: =IF(COUNTIF(I17:I38,"="&IncompleteText),IncompleteText,IF(COUNTIF(I17:I38,"="&ErrorText),ErrorText,OKText)) -> BLANK | K15: 规则参考/注释 Rules Reference/Comment | O15: Location List
A16: 制造商 Manufacturer | B16: 型号 Part number | C16: 载流截面积 Size [mm2] | D16: 额定电压 Nominal Voltage [Vdc] | E16: 额定电流 Nominal Current [A] | F16: 最大工作温度 Max Temp[C] | G16: 说明书链接 Datasheet Hyperlink | H16: 位置 Location | I16: 判定 Auto-check | J16: 注释 Additional Info | K16: -如果在不同位置使用了相同的导体，请增加一行重复的输入项目。 -如果相同段落使用了多种导体，每一种导体信息都应该被填入 - 本表格更多指向铜牌，导线等 -如果使用位置是'其他驱动系统’，请在注释列填写说明 -检查项目包括但不限于： -第五章 -- 5.1.2 -- 5.1.3 -- 5.5.3 -- 5.5.5 本页表格允许添加行 ———— - If the same conductor is used in different locations, please add an additional row with the repeated input item. - If multiple types of conductors are used in the same section, information for each conductor should be filled in. - If the usage location is 'Other TS,' please provide an explanation in the Additional Info column. - Rows can be added to the table on this page. | M16: ` | O16: 电芯之间 Between cells
I17: =IF(COUNTBLANK(A17:H17)=8,IncompleteText,IF(AND(COUNTBLANK(A17:H17)=0,F17>=85),IF(AND(H17="其他驱动系统",COUNTBLANK(J17)=1),ErrorText,OKText),ErrorText)) -> BLANK | O17: 电芯到AIR Between cells and AIR
I18: =IF(COUNTBLANK(A18:H18)=8,"",IF(AND(COUNTBLANK(A18:H18)=0,F18>=85),IF(AND(H18="其他驱动系统",COUNTBLANK(J18)=1),ErrorText,OKText),ErrorText)) | O18: AIR到电池箱连接器 Between AIR and Acc Connector
I19: =IF(COUNTBLANK(A19:H19)=8,"",IF(AND(COUNTBLANK(A19:H19)=0,F19>=85),IF(AND(H19="其他驱动系统",COUNTBLANK(J19)=1),ErrorText,OKText),ErrorText)) | O19: 电池箱到电机控制器 Between Acc and Motor Controller
I20: =IF(COUNTBLANK(A20:H20)=8,"",IF(AND(COUNTBLANK(A20:H20)=0,F20>=85),IF(AND(H20="其他驱动系统",COUNTBLANK(J20)=1),ErrorText,OKText),ErrorText)) | O20: 电池箱到能量计Between Acc and Energy Meter
I21: =IF(COUNTBLANK(A21:H21)=8,"",IF(AND(COUNTBLANK(A21:H21)=0,F21>=85),IF(AND(H21="其他驱动系统",COUNTBLANK(J21)=1),ErrorText,OKText),ErrorText)) | O21: 能量计到电机控制器 Between Energy Meter and Motor Controller
I22: =IF(COUNTBLANK(A22:H22)=8,"",IF(AND(COUNTBLANK(A22:H22)=0,F22>=85),IF(AND(H22="其他驱动系统",COUNTBLANK(J22)=1),ErrorText,OKText),ErrorText)) | O22: TSMP采样线 TSMP detection wires
I23: =IF(COUNTBLANK(A23:H23)=8,"",IF(AND(COUNTBLANK(A23:H23)=0,F23>=85),IF(AND(H23="其他驱动系统",COUNTBLANK(J23)=1),ErrorText,OKText),ErrorText)) | O23: TSAL采样线 TSAL detection wire
I24: =IF(COUNTBLANK(A24:H24)=8,"",IF(AND(COUNTBLANK(A24:H24)=0,F24>=85),IF(AND(H24="其他驱动系统",COUNTBLANK(J24)=1),ErrorText,OKText),ErrorText)) | O24: 电芯单体采样线 Cell Volt Detection
O25: 电机控制器到电机 Between Motor Controller and Motors
I26: =IF(COUNTBLANK(A26:H26)=8,"",IF(AND(COUNTBLANK(A26:H26)=0,F26>=85),IF(AND(H26="其他驱动系统",COUNTBLANK(J26)=1),ErrorText,OKText),ErrorText)) | O26: 电池箱到HVD Between ACC and HVD
I27: =IF(COUNTBLANK(A27:H27)=8,"",IF(AND(COUNTBLANK(A27:H27)=0,F27>=85),IF(AND(H27="其他驱动系统",COUNTBLANK(J27)=1),ErrorText,OKText),ErrorText)) | O27: HVD到电机控制器, Between Motor Controller and HVD
I28: =IF(COUNTBLANK(A28:H28)=8,"",IF(AND(COUNTBLANK(A28:H28)=0,F28>=85),IF(AND(H28="其他驱动系统",COUNTBLANK(J28)=1),ErrorText,OKText),ErrorText)) | O28: 预充电回路 Precharge
I29: =IF(COUNTBLANK(A29:H29)=8,"",IF(AND(COUNTBLANK(A29:H29)=0,F29>=85),IF(AND(H29="其他驱动系统",COUNTBLANK(J29)=1),ErrorText,OKText),ErrorText)) | O29: 放电回路 Discharge
I30: =IF(COUNTBLANK(A30:H30)=8,"",IF(AND(COUNTBLANK(A30:H30)=0,F30>=85),IF(AND(H30="其他驱动系统",COUNTBLANK(J30)=1),ErrorText,OKText),ErrorText)) | O30: 充电机DC侧 Charging DC side
I31: =IF(COUNTBLANK(A31:H31)=8,"",IF(AND(COUNTBLANK(A31:H31)=0,F31>=85),IF(AND(H31="其他驱动系统",COUNTBLANK(J31)=1),ErrorText,OKText),ErrorText)) | O31: 充电机AC侧 Charging AC side
I32: =IF(COUNTBLANK(A32:H32)=8,"",IF(AND(COUNTBLANK(A32:H32)=0,F32>=85),IF(AND(H32="其他驱动系统",COUNTBLANK(J32)=1),ErrorText,OKText),ErrorText)) | O32: 其他驱动系统 Other TS
I33: =IF(COUNTBLANK(A33:H33)=8,"",IF(AND(COUNTBLANK(A33:H33)=0,F33>=85),IF(AND(H33="其他驱动系统",COUNTBLANK(J33)=1),ErrorText,OKText),ErrorText)) | O33: 安全回路 Shutdown circuit
I34: =IF(COUNTBLANK(A34:H34)=8,"",IF(AND(COUNTBLANK(A34:H34)=0,F34>=85),IF(AND(H34="其他驱动系统",COUNTBLANK(J34)=1),ErrorText,OKText),ErrorText)) | O34: 其他低压系统 Other LVS
I35: =IF(COUNTBLANK(A35:H35)=8,"",IF(AND(COUNTBLANK(A35:H35)=0,F35>=85),IF(AND(H35="其他驱动系统",COUNTBLANK(J35)=1),ErrorText,OKText),ErrorText))
I36: =IF(COUNTBLANK(A36:H36)=8,"",IF(AND(COUNTBLANK(A36:H36)=0,F36>=85),IF(AND(H36="其他驱动系统",COUNTBLANK(J36)=1),ErrorText,OKText),ErrorText))
I37: =IF(COUNTBLANK(A37:H37)=8,"",IF(AND(COUNTBLANK(A37:H37)=0,F37>=85),IF(AND(H37="其他驱动系统",COUNTBLANK(J37)=1),ErrorText,OKText),ErrorText))
I38: =IF(COUNTBLANK(A38:H38)=8,"",IF(AND(COUNTBLANK(A38:H38)=0,F38>=85),IF(AND(H38="其他驱动系统",COUNTBLANK(J38)=1),ErrorText,OKText),ErrorText))
A40: 过流保护器件 Fuses | I40: =IF(COUNTIF(I42:I53,"="&IncompleteText),IncompleteText,IF(COUNTIF(I42:I53,"="&ErrorText),ErrorText,OKText)) -> BLANK | J40: 规则参考/注释 Rules Reference/Comment
A41: 制造商 Manufacturer | B41: 型号 Part number | C41: 额定电压Nominal Voltage [Vdc] | D41: 额定电流 Nominal Current [A] | E41: 额定分断电流 Interrupt (A) | F41: 最大工作温度 Max Temp[C] | G41: =G16 -> 说明书链接 Datasheet Hyperlink | H41: =H16 -> 位置 Location | I41: 判定 Auto-check | J41: 注释 Additional Info | K41: - 如果使用位置是'其他驱动系统’，请在注释列填写说明，且关于位置的表述必须和之前的导体段落文本完全一致 - 检查的项目包括但不限于 - 第五章 3.2 ———— If the usage location is 'Other TS,' please provide an explanation in the Additional Info column. It must the same as the expression in the 'Conductor' part
I42: =IF(COUNTBLANK(A42:H42)=8,IncompleteText,IF(AND(COUNTBLANK(A42:H42)=0,F42>=85),IF(AND(H42="其他驱动系统",COUNTBLANK(J42)=1),ErrorText,OKText),ErrorText)) -> BLANK
...

Sheet 驱动系统原理图 TS Schematics
A1: 状态 Status | B1: {=IF(SUM(COUNTIF(INDIRECT({"$K$28","$W$28","$K$48"}),"="&IncompleteText)),IncompleteText,IF(SUM(COUNTIF(INDIRECT({"$K$28","$W$28","$K$48"}),"="&ErrorText)),ErrorText,OKText))} -> BLANK
A2: 电池以外驱动系统原理图 Vehicle Tractive Schematics | M2: 电池箱内部原理图 请参考左图尺寸插入图片 Internal schematic diagram of the accumulator box Please refer to the dimensions of the left diagram to insert the image. | Y2: 补充内容 Additional comments
Y3: Fill upon request 需要时填写
A28: 电池以外驱动系统原理图 Vehicle Tractive Schematics | K28: =IF(COUNTIF(K30:K46,"="&IncompleteText),IncompleteText,IF(COUNTIF(K30:K46,"="&ErrorText),ErrorText,OKText)) -> BLANK | M28: 电池箱内部原理图 Accumulator TS Schematic | W28: =IF(COUNTIF(W30:W43,"="&IncompleteText),IncompleteText,IF(COUNTIF(W30:W43,"="&ErrorText),ErrorText,OKText)) -> BLANK
A29: 规则参考,Rule ref CN only, | M29: 规则参考,Rule ref CN only,
C30: 展示电池箱以外驱动系统所有细节 Show details of all TS outside of accumulator | K30: =IF(ISBLANK(J30),IncompleteText,IF(J30,OKText,ErrorText)) -> BLANK | O30: 电池箱内部驱动系统细节 Details of all TS circuits within accumulator | W30: =IF(ISBLANK(V30),IncompleteText,IF(V30,OKText,ErrorText)) -> BLANK
C31: 电池箱被作为一个整体呈现(AIR除外) Accumulator is shown as a single element (without internal details) | K31: =IF(ISBLANK(J31),IncompleteText,IF(J31,OKText,ErrorText)) -> BLANK | O31: 所有的线径都有标注 All wire gauges labeled | W31: =IF(ISBLANK(V31),IncompleteText,IF(V31,OKText,ErrorText)) -> BLANK
A32: 第五章 5.5.5 | C32: 所有的线径都有标注 All wire guages labeled | K32: =IF(ISBLANK(J32),IncompleteText,IF(J32,OKText,ErrorText)) -> BLANK | O32: 所有的保险丝都有标注额定电流 All fuses are labeled with their ampacity | W32: =IF(ISBLANK(V32),IncompleteText,IF(V32,OKText,ErrorText)) -> BLANK
C33: 所有的保险丝都有标注额定电流 All fuses labedled with ampacity | K33: =IF(ISBLANK(J33),IncompleteText,IF(J33,OKText,ErrorText)) -> BLANK | O33: 保险丝距离电源侧线缆的距离(未保护线缆长度）Distance from fuses to positive power souces | W33: =IF(ISBLANK(V33),IncompleteText,IF(V33,OKText,ErrorText)) -> BLANK
C34: 保险丝位置应当对应其真实物理位置（壳体）Fuse locations represent physical location | K34: =IF(ISBLANK(J34),IncompleteText,IF(J34,OKText,ErrorText)) -> BLANK | O34: 保险丝位置应当对应其真实物理位置 Fuse locations represent physical location | W34: =IF(ISBLANK(V34),IncompleteText,IF(V34,OKText,ErrorText)) -> BLANK
A35: 第五章 5.2 | C35: 驱动系统壳体 TS enclosures | K35: =IF(ISBLANK(J35),IncompleteText,IF(J35,OKText,ErrorText)) -> BLANK | O35: 接插件标注有制造商/型号 Connectors labeled with Make/Model | W35: =IF(ISBLANK(V35),IncompleteText,IF(V35,OKText,ErrorText)) -> BLANK
C36: 接插件标注有制造商/型号 Connectors labeled with Make/Model | K36: =IF(ISBLANK(J36),IncompleteText,IF(J36,OKText,ErrorText)) -> BLANK | O36: 使用通用的原理图符号 Standard schematic symbols used | W36: =IF(ISBLANK(V36),IncompleteText,IF(V36,OKText,ErrorText)) -> BLANK
C37: 使用通用的原理图符号 Standard schematic symbols used | K37: =IF(ISBLANK(J37),IncompleteText,IF(J37,OKText,ErrorText)) -> BLANK | O37: 文字放大后清晰 All text iis readable, zooming allowed | W37: =IF(ISBLANK(V37),IncompleteText,IF(V37,OKText,ErrorText)) -> BLANK
C38: 文字放大后清晰 All text iis readable, zooming allowed | K38: =IF(ISBLANK(J38),IncompleteText,IF(J38,OKText,ErrorText)) -> BLANK | M38: 第五章 6.6 | O38: AIRs | W38: =IF(ISBLANK(V38),IncompleteText,IF(V38,OKText,ErrorText)) -> BLANK
A39: 第五章 5.7 | C39: TSMPs | K39: =IF(ISBLANK(J39),IncompleteText,IF(J39,OKText,ErrorText)) -> BLANK | M39: 第五章 6.4.4 | O39: 维护插头 Maintenance plugs | W39: =IF(ISBLANK(V39),IncompleteText,IF(V39,OKText,ErrorText)) -> BLANK
C40: 电机控制器 Motor controllers | K40: =IF(ISBLANK(J40),IncompleteText,IF(J40,OKText,ErrorText)) -> BLANK | O40: 电芯（电芯互联的部分可以简略）Cells (intercell connections may be abstracted) | W40: =IF(ISBLANK(V40),IncompleteText,IF(V40,OKText,ErrorText)) -> BLANK
C41: 电机 Motors | K41: =IF(ISBLANK(J41),IncompleteText,IF(J41,OKText,ErrorText)) -> BLANK | M41: 第五章6.4.8 | O41: 电池箱高压指示器 High voltage indicator | W41: =IF(ISBLANK(V41),IncompleteText,IF(V41,OKText,ErrorText)) -> BLANK
A42: 第五章 5..7.6 | C42: TSMP没有熔断 TSMP not fused | K42: =IF(ISBLANK(J42),IncompleteText,IF(J42,OKText,ErrorText)) -> BLANK | M42: 第五章 6.7 | O42: 预充电回路 Precharge circuit | W42: =IF(ISBLANK(V42),IncompleteText,IF(V42,OKText,ErrorText)) -> BLANK
A43: 第五章 5.6 | C43: 数据记录仪 Energy Meter/Data Logger | K43: =IF(ISBLANK(J43),IncompleteText,IF(J43,OKText,ErrorText)) -> BLANK | O43: 预充电回路过流保护 precharge circuit overcurrent protections | W43: =IF(ISBLANK(V43),IncompleteText,IF(V43,OKText,ErrorText)) -> BLANK
A44: 第五章 5.9 | C44: 放电回路 Discharge circuit | K44: =IF(ISBLANK(J44),IncompleteText,IF(J44,OKText,ErrorText)) -> BLANK
A45: 第五章 5.9.3 | C45: 放电回路未熔断 Discharge not fused | K45: =IF(ISBLANK(J45),IncompleteText,IF(J45,OKText,ErrorText)) -> BLANK
A46: 第五章 5.8 | C46: HVD | K46: =IF(ISBLANK(J46),IncompleteText,IF(J46,OKText,ErrorText)) -> BLANK
A48: 至少在其中一副原理图中展示 Must shown on at least one schematic | K48: =IF(COUNTIF(K50:K50,"="&IncompleteText),IncompleteText,IF(COUNTIF(K50:K50,"="&ErrorText),ErrorText,OKText)) -> BLANK
A49: 规则参考,Rule ref CN only,
A50: 第五章 7.4 | C50: IMD | K50: =IF(ISBLANK(J50),IncompleteText,IF(J50,OKText,ErrorText)) -> BLANK

Sheet 电池箱 Accumulator
A1: 状态 Status | B1: {=IF(SUM(COUNTIF(INDIRECT({"$G$3","$G$4","$J$8","$Q$8","$W$8","$AD$8","$Z$52","$Q$52","$H$52","$F$61","$H$83"}),"="&IncompleteText)),IncompleteText,IF(SUM(COUNTIF(INDIRECT({"$G$3","$G$4","$J$8","$Q$8","$W$8","$AD$8","$Z$52","$Q$52","$H$52","$F$61","$H$82"}),"="&ErrorText)),ErrorText,OKText))} -> BLANK
A3: 模组连接关系 Segment-to-Segment Connection | G3: =IF(ISBLANK(E3),IncompleteText,OKText) -> BLANK
A4: 驱动系统最大电压 Max TS voltage | E4: {=IF(E3="串联 Serial",SUM(C12:C29)*BattCellMaxV,C12*BattCellMaxV*SUM(IF(FREQUENCY(E12:E29,E12:E29)>0,1)))} -> 0 | F4: V | G4: =IF(MaxTSVoltage=0,IncompleteText,IF(E4>600,ErrorText,OKText)) -> BLANK
A5: 驱动系统额定电压 Nominal TS voltage | E5: {=IF(E3="串联 Serial",SUM(C12:C29)*BattCellNomV,C12*BattCellNomV*SUM(IF(FREQUENCY(E12:E29,E12:E29)>0,1)))} -> 0 | F5: V
A6: 电池单体数量 Total cells | E6: =SUMPRODUCT(B12:B29,C12:C29) -> 0
A8: 模组数据 Segement data | J8: =IF(COUNTIF(J9:J29,"="&IncompleteText),IncompleteText,IF(COUNTIF(J9:J29,"="&ErrorText),ErrorText,OKText)) -> BLANK | K8: BMS | Q8: =IF(COUNTIF(Q9:Q30,"="&IncompleteText),IncompleteText,IF(COUNTIF(Q9:Q30,"="&ErrorText),ErrorText,OKText)) -> BLANK | R8: 维护插头 Maintenance Plugs | W8: =IF(COUNTIF(W9:W21,"="&IncompleteText),IncompleteText,IF(COUNTIF(W9:W21,"="&ErrorText),ErrorText,OKText)) -> BLANK | X8: 绝缘材料 Insulating Materials | AD8: =IF(COUNTIF(AD9:AD18,"="&IncompleteText),IncompleteText,IF(COUNTIF(AD9:AD18,"="&ErrorText),ErrorText,OKText)) -> BLANK | AE8: 补充说明 Additional Comments
A9: 电芯串并关系 Cell connection order | J9: =IF(ISBLANK(D9),IncompleteText,OKText) -> BLANK | K9: BMS拓扑 BMS Type | Q9: =IF(ISBLANK(O9),IncompleteText,OKText) -> BLANK | R9: 接插件/连接器 Connector | W9: =IF(ISBLANK(U9),IncompleteText,OKText) -> BLANK | X9: 电芯及电池箱内壁之间绝缘材料 Between cells and accumulator | AD9: =IF(ISBLANK(AB9),IncompleteText,OKText) -> BLANK
A10: 模组编号 Segement | B10: 并联数 Parallel cells | C10: 串联数 Serial cells | D10: 温度测点数量 Temp sensors | E10: 电池箱编号 Accumulator number | F10: 模组最大电压 Max Voltage[V] | H10: 模组能量 Segement energy [MJ] | K10: BMS来源 BMS source | Q10: =IF(ISBLANK(O10),IncompleteText,OKText) -> BLANK | R10: 额定电流 Ampacity | U10: =VLOOKUP(U9,ConnectorTable,3,FALSE) -> #N/A | V10: A | W10: =IF(ISERROR(U10),IncompleteText,IF(E3="串联 Serial",IF(U10>=U20,OKText,ErrorText),IF(E3="并联 Parallel",IF(U10>=U12,OKText,ErrorText),IncompleteText))) -> BLANK | X10: 电压等级 Voltage Rating | AB10: =VLOOKUP(AB9,InsulationsTable,4,FALSE) -> #N/A | AC10: V | AD10: =IF(ISERROR(AB10),IncompleteText,IF(AB10<MaxTSVoltage,ErrorText,OKText)) -> BLANK
K11: 制造商 Make | N11: 型号 Type | Q11: =IF(O10="供应商提供 From Suppliers",IF(OR(ISBLANK(L11),ISBLANK(O11)),IncompleteText,OKText),"") | R11: 对应保险丝 Fuse provides protections | W11: =IF(E3="串联 Serial","",IF(ISBLANK(U11),IncompleteText,OKText)) -> BLANK | X11: 温度等级 Temperature Rating | AB11: =VLOOKUP(AB9,InsulationsTable,5,FALSE) -> #N/A | AC11: C | AD11: =IF(ISERROR(AB11),IncompleteText,IF(AB11<90,ErrorText,OKText)) -> BLANK
A12: 1 | F12: =C12*BattCellMaxV -> 0 | H12: =F12*B12*BattCellCapacity*0.0036 -> 0 | J12: =IF(COUNTBLANK(A12:E12)>0,IncompleteText,IF(OR(F12>120,H12>6),ErrorText,OKText)) -> BLANK | K12: 驱动系统到低压控制系统绝缘电压 Galvanic Isolation TS to LVS | P12: V | Q12: =IF(ISBLANK(O12),IncompleteText,IF(O12<E4,ErrorText,OKText)) -> BLANK | R12: 保险丝额定电流 Fuse ampacity | U12: =VLOOKUP(U11,FuseTable,3,FALSE) -> #N/A | V12: A | X12: 电芯上方覆盖 On top of cells | AD12: =IF(ISBLANK(AB12),IncompleteText,OKText) -> BLANK
A13: 2 | F13: =C13*BattCellMaxV -> 0 | H13: =F13*B13*BattCellCapacity*0.0036 -> 0 | J13: =IF(COUNTBLANK(A13:E13)=4,"",IF(COUNTBLANK(A13:E13)>0,IncompleteText,IF(OR(F13>120,H13>6),ErrorText,OKText))) | K13: 模组间绝缘电压 Galvanic Isolation between segments | P13: V | Q13: =IF(ISBLANK(O13),IncompleteText,IF(O13<MAX(F12:G29),ErrorText,OKText)) -> BLANK | R13: AIR | X13: 电压等级 Voltage Rating | AB13: =VLOOKUP(AB12,InsulationsTable,4,FALSE) -> #N/A | AC13: V | AD13: =IF(ISERROR(AB13),IncompleteText,IF(AB13<MaxTSVoltage,ErrorText,OKText)) -> BLANK
A14: 3 | F14: =C14*BattCellMaxV -> 0 | H14: =F14*B14*BattCellCapacity*0.0036 -> 0 | J14: =IF(COUNTBLANK(A14:E14)=4,"",IF(COUNTBLANK(A14:E14)>0,IncompleteText,IF(OR(F14>120,H14>6),ErrorText,OKText))) | K14: 隔离器件 Galvanic Isolation devices | Q14: =IF($O$10="车队自制 Team design",IF(ISBLANK(O14),IncompleteText,OKText),"") | R14: 型号 Make/Model | W14: =IF(ISBLANK(U14),IncompleteText,OKText) -> BLANK | X14: 温度等级 Temperature Rating | AB14: =VLOOKUP(AB12,InsulationsTable,5,FALSE) -> #N/A | AC14: C | AD14: =IF(ISERROR(AB14),IncompleteText,IF(AB14<90,ErrorText,OKText)) -> BLANK
A15: 4 | F15: =C15*BattCellMaxV -> 0 | H15: =F15*B15*BattCellCapacity*0.0036 -> 0 | J15: =IF(COUNTBLANK(A15:E15)=4,"",IF(COUNTBLANK(A15:E15)>0,IncompleteText,IF(OR(F15>120,H15>6),ErrorText,OKText))) | K15: 隔离器件说明书 Galvanic Isolation devices datasheets | Q15: =IF($O$10="车队自制 Team design",IF(ISBLANK(O15),IncompleteText,OKText),"") | R15: 触点额定电压 Contactnoimal volatge | U15: =VLOOKUP(U14,ContactorsTable,2,FALSE) -> #N/A | V15: Vdc | W15: =IF(ISERROR(U15),IncompleteText,IF(U15<MaxTSVoltage,ErrorText,OKText)) -> BLANK | X15: AIR,主保险丝与电芯之间 Between AIRs and Cells | AD15: =IF(ISBLANK(AB15),IncompleteText,OKText) -> BLANK
A16: 5 | F16: =C16*BattCellMaxV -> 0 | H16: =F16*B16*BattCellCapacity*0.0036 -> 0 | J16: =IF(COUNTBLANK(A16:E16)=4,"",IF(COUNTBLANK(A16:E16)>0,IncompleteText,IF(OR(F16>120,H16>6),ErrorText,OKText))) | K16: 电芯电压测量 Voltage Sense Leads | R16: 最大分断电流 Max switching current | U16: =VLOOKUP(U14,ContactorsTable,4,FALSE) -> #N/A | V16: A | X16: 电压等级 Voltage Rating | AB16: =VLOOKUP(AB15,InsulationsTable,4,FALSE) -> #N/A | AC16: V | AD16: =IF(ISERROR(AB16),IncompleteText,IF(AB16<MaxTSVoltage,ErrorText,OKText)) -> BLANK
A17: 6 | F17: =C17*BattCellMaxV -> 0 | H17: =F17*B17*BattCellCapacity*0.0036 -> 0 | J17: =IF(COUNTBLANK(A17:E17)=4,"",IF(COUNTBLANK(A17:E17)>0,IncompleteText,IF(OR(F17>120,H17>6),ErrorText,OKText))) | K17: 最长采样线线缆长度 Max lead length | P17: cm | Q17: =IF(ISBLANK(O17),IncompleteText,OKText) -> BLANK | R17: 额定电流 Max continuous current | U17: =VLOOKUP(U14,ContactorsTable,3,FALSE) -> #N/A | V17: A | W17: =IF(ISERROR(U17),IncompleteText,IF(U17>=U20,OKText,ErrorText)) -> BLANK | X17: 温度等级 Temperature Rating | AB17: =VLOOKUP(AB15,InsulationsTable,5,FALSE) -> #N/A | AC17: C | AD17: =IF(ISERROR(AB17),IncompleteText,IF(AB17<90,ErrorText,OKText)) -> BLANK
A18: 7 | F18: =C18*BattCellMaxV -> 0 | H18: =F18*B18*BattCellCapacity*0.0036 -> 0 | J18: =IF(COUNTBLANK(A18:E18)=4,"",IF(COUNTBLANK(A18:E18)>0,IncompleteText,IF(OR(F18>120,H18>6),ErrorText,OKText))) | K18: 采样线过流保护器件型号 Sense lead overprotection device | Q18: =IF(ISBLANK(O18),IncompleteText,OKText) -> BLANK | R18: 主保险丝 Main Fuse | X18: 防火等级 Flammability Rating | AB18: =VLOOKUP(AB15,InsulationsTable,6,FALSE) -> #N/A | AD18: =IF(ISNA(AB18),IncompleteText,OKText) -> BLANK
A19: 8 | F19: =C19*BattCellMaxV -> 0 | H19: =F19*B19*BattCellCapacity*0.0036 -> 0 | J19: =IF(COUNTBLANK(A19:E19)=4,"",IF(COUNTBLANK(A19:E19)>0,IncompleteText,IF(OR(F19>120,H19>6),ErrorText,OKText))) | K19: 过流保护器件位置 Overcurrent protection device location | Q19: =IF(ISBLANK(O19),IncompleteText,OKText) -> BLANK | R19: 主保险丝 Main Fuse | W19: =IF(ISBLANK(U19),IncompleteText,OKText) -> BLANK
A20: 9 | F20: =C20*BattCellMaxV -> 0 | H20: =F20*B20*BattCellCapacity*0.0036 -> 0 | J20: =IF(COUNTBLANK(A20:E20)=4,"",IF(COUNTBLANK(A20:E20)>0,IncompleteText,IF(OR(F20>120,H20>6),ErrorText,OKText))) | K20: 其他位置说明 | Q20: =IF(O19="其他 Other",IF(ISBLANK(O20),IncompleteText,OKText),"") | R20: 额定电流 Max fuse ampacity | U20: =VLOOKUP(U19,FuseTable,3,FALSE) -> #N/A | V20: A
A21: 10 | F21: =C21*BattCellMaxV -> 0 | H21: =F21*B21*BattCellCapacity*0.0036 -> 0 | J21: =IF(COUNTBLANK(A21:E21)=4,"",IF(COUNTBLANK(A21:E21)>0,IncompleteText,IF(OR(F21>120,H21>6),ErrorText,OKText))) | K21: 过流保护电压等级 Overcurrent voltage rating | O21: =VLOOKUP(O18,FuseTable,2,FALSE) -> #N/A | Q21: =IF(ISERROR(O21),IncompleteText,IF(AND(O21<MAX(F12:G29),O9="集中式 Centralized"),ErrorText,OKText)) -> BLANK | R21: 额定电压 Main fuse voltage | U21: =VLOOKUP(U19,FuseTable,2,FALSE) -> #N/A | V21: V | W21: =IF(U21<MaxTSVoltage,ErrorText,OKText) -> #N/A
A22: 11 | F22: =C22*BattCellMaxV -> 0 | H22: =F22*B22*BattCellCapacity*0.0036 -> 0 | J22: =IF(COUNTBLANK(A22:E22)=4,"",IF(COUNTBLANK(A22:E22)>0,IncompleteText,IF(OR(F22>120,H22>6),ErrorText,OKText))) | K22: 温度传感器
A23: 12 | F23: =C23*BattCellMaxV -> 0 | H23: =F23*B23*BattCellCapacity*0.0036 -> 0 | J23: =IF(COUNTBLANK(A23:E23)=4,"",IF(COUNTBLANK(A23:E23)>0,IncompleteText,IF(OR(F23>120,H23>6),ErrorText,OKText))) | K23: 温度传感器位置 Temp sensor location | Q23: =IF(ISBLANK(O23),IncompleteText,OKText) -> BLANK
A24: 13 | F24: =C24*BattCellMaxV -> 0 | H24: =F24*B24*BattCellCapacity*0.0036 -> 0 | J24: =IF(COUNTBLANK(A24:E24)=4,"",IF(COUNTBLANK(A24:E24)>0,IncompleteText,IF(OR(F24>120,H24>6),ErrorText,OKText))) | K24: 距离极耳距离 Distance to terminal | P24: mm | Q24: =IF(O23="极耳 Cell tabs","",IF(ISBLANK(O24),IncompleteText,IF(O24<10,OKText,ErrorText))) -> BLANK
A25: 14 | F25: =C25*BattCellMaxV -> 0 | H25: =F25*B25*BattCellCapacity*0.0036 -> 0 | J25: =IF(COUNTBLANK(A25:E25)=4,"",IF(COUNTBLANK(A25:E25)>0,IncompleteText,IF(OR(F25>120,H25>6),ErrorText,OKText))) | K25: 单个测点测量的电芯数量 Cells sensed per sensor | P25: cells | Q25: =IF(ISBLANK(O25),IncompleteText,OKText) -> BLANK
A26: 15 | F26: =C26*BattCellMaxV -> 0 | H26: =F26*B26*BattCellCapacity*0.0036 -> 0 | J26: =IF(COUNTBLANK(A26:E26)=4,"",IF(COUNTBLANK(A26:E26)>0,IncompleteText,IF(OR(F26>120,H26>6),ErrorText,OKText))) | K26: 导热材料型号(如果有) Thermal contact material (if used)
A27: 16 | F27: =C27*BattCellMaxV -> 0 | H27: =F27*B27*BattCellCapacity*0.0036 -> 0 | J27: =IF(COUNTBLANK(A27:E27)=4,"",IF(COUNTBLANK(A27:E27)>0,IncompleteText,IF(OR(F27>120,H27>6),ErrorText,OKText))) | K27: 导热材料说明书链接 Thermal contact material datasheet | Q27: =IF(ISBLANK($O$26),"",IF(ISBLANK(O27),IncompleteText,OKText))
A28: 17 | F28: =C28*BattCellMaxV -> 0 | H28: =F28*B28*BattCellCapacity*0.0036 -> 0 | J28: =IF(COUNTBLANK(A28:E28)=4,"",IF(COUNTBLANK(A28:E28)>0,IncompleteText,IF(OR(F28>120,H28>6),ErrorText,OKText))) | K28: 导热材料热导率 Thermal contact material conductivity | P28: W/(m∙K) | Q28: =IF(ISBLANK($O$26),"",IF(ISBLANK(O28),IncompleteText,OKText))
A29: 18 | F29: =C29*BattCellMaxV -> 0 | H29: =F29*B29*BattCellCapacity*0.0036 -> 0 | J29: =IF(COUNTBLANK(A29:E29)=4,"",IF(COUNTBLANK(A29:E29)>0,IncompleteText,IF(OR(F29>120,H29>6),ErrorText,OKText))) | K29: 导热材料厚度 Thermal contact material thickness | P29: mm | Q29: =IF(ISBLANK($O$26),"",IF(ISBLANK(O29),IncompleteText,OKText))
K30: 温度测量覆盖率 Precentage of cells sensed | O30: =SUMIF(J12:J29,"=OK",D12:D29)*CellsPerTempSensor/TotalCells*100 -> #DIV/0! | P30: % | Q30: =IF(ISERROR(O30),IncompleteText,IF(O30<20,ErrorText,OKText)) -> BLANK
A33: 维护插头示意图/照片 Pictures of Maintenance Plugs | J33: 极耳连接以及电芯固定示意图/照片 Picture of Cell Connections | S33: 温度传感器布置图 Picture of Temperature Sensor Location | AB33: 主保险丝和AIR和电芯分隔 Picture of Fuse and AIR Separation from cells | AK33: 电芯与电池箱内壁的绝缘 Picture of Segment Insulation between Cell Terminal and Sides of Accumulator Container | AT33: 模组上方绝缘 Picture of Insulation on Top of Segment
A52: 维护插头示意图/照片 Pictures of Maintenance Plugs | H52: =IF(COUNTIF(H53:H56,"="&IncompleteText),IncompleteText,IF(COUNTIF(H53:H55,"="&ErrorText),ErrorText,OKText)) -> BLANK | J52: 极耳连接以及电芯固定示意图/照片 Picture of Cell Connections | Q52: =IF(COUNTIF(Q53:Q55,"="&IncompleteText),IncompleteText,IF(COUNTIF(Q53:Q55,"="&ErrorText),ErrorText,OKText)) -> BLANK | S52: 温度传感器布置图 Picture of Temperature Sensor Location | Z52: =IF(COUNTIF(Z53:Z54,"="&IncompleteText),IncompleteText,IF(COUNTIF(Z53:Z54,"="&ErrorText),ErrorText,OKText)) -> BLANK | AB52: 主保险丝和AIR和电芯分隔 Picture of Fuse and AIR Separation from cells | AI52: =IF(COUNTIF(AI53,"="&IncompleteText),IncompleteText,IF(COUNTIF(AI53,"="&ErrorText),ErrorText,OKText)) -> BLANK | AK52: 模组绝缘 Segment Insulation | AR52: =IF(COUNTIF(AR53,"="&IncompleteText),IncompleteText,IF(COUNTIF(AR53,"="&ErrorText),ErrorText,OKText)) -> BLANK | AT52: 模组上方绝缘 Insulation on Top of Segment | BA52: =IF(COUNTIF(BA53,"="&IncompleteText),IncompleteText,IF(COUNTIF(BA53,"="&ErrorText),ErrorText,OKText)) -> BLANK
A53: 防止误插 Unique configurations of plugs | H53: =IF(ISBLANK(G53),IncompleteText,IF(G53,OKText,ErrorText)) -> BLANK | J53: 如果极耳采用紧固件压接，紧固件防松 Positive locking if bolted connections | Q53: =IF(ISBLANK(P53),IncompleteText,IF(P53,OKText,ErrorText)) -> BLANK | S53: 温度传感器直接接触极耳或者总线 Sensor in direct contact with terminal or busbar | Z53: =IF(ISBLANK(Y53),IncompleteText,IF(Y53,OKText,ErrorText)) -> BLANK | AB53: 主保险丝和AIR和电芯分隔 Fuse and AIR Separation from cells | AI53: =IF(ISBLANK(AH53),IncompleteText,IF(AH53,OKText,ErrorText)) -> BLANK | AK53: 电芯和电池箱内部绝缘 Insulation between cells and accumulator | AR53: =IF(ISBLANK(AQ53),IncompleteText,IF(AQ53,OKText,ErrorText)) -> BLANK | AT53: 模组上方绝缘 Insulation on Top of Segment | BA53: =IF(ISBLANK(AZ53),IncompleteText,IF(AZ53,OKText,ErrorText)) -> BLANK
A54: 非载流面绝缘 Non-conductive on un-necessary surface | H54: =IF(ISBLANK(G54),IncompleteText,IF(G54,OKText,ErrorText)) -> BLANK | J54: 极耳不受机械负载 No mechanic load on cell tabs | Q54: =IF(ISBLANK(P54),IncompleteText,IF(P54,OKText,ErrorText)) -> BLANK | S54: 未直接接触但足够近 Distance from sensor to cell negative terminal sufficienly close | Z54: =IF(ISBLANK(Y54),IncompleteText,IF(Y54,OKText,ErrorText)) -> BLANK | AB54: 补充说明 Additional Comments | AI54: 规则参考 Rules Ref | AK54: 补充说明 Additional Comments | AR54: 规则参考 Rules Ref | AT54: 补充说明 Additional Comments | BA54: 规则参考 Rules Ref
A55: 安装不需要拆除电池箱部件 Accessible without additional desassembly | H55: =IF(ISBLANK(G55),IncompleteText,IF(G55,OKText,ErrorText)) -> BLANK | J55: 电芯在各个方向有限位，且受力面没有过小 Positions limits on all directions, sufficient surface with load | Q55: =IF(ISBLANK(P55),IncompleteText,IF(P55,OKText,ErrorText)) -> BLANK | S55: 补充说明 Additional Comments | Z55: 规则参考 Rules Ref | AI55: 第五章 6.5.12 | AR55: 第五章 6.4.1 6.5.8 | BA55: 第五章 6.4.6
A56: 主动锁紧/防松 Postive locking | H56: =IF(ISBLANK(G56),IncompleteText,IF(G56,OKText,ErrorText)) -> BLANK | J56: 电芯受力面应当占该表面的80% Surface with load: >= 80% | Q56: Recommended
A57: 补充说明 Additional Comments | H57: 规则参考 Rules Ref | J57: 补充说明 Additional Comments | Q57: 规则参考 Rules Ref | Z57: 第五章 6.8.4
H58: 第五章 6.4.4 6.4.5 | Q58: 第五章 6.5.10
A64: 电池箱高压指示器原理图 Accumulator HV indicator
A83: 电池箱高压指示器原理图 Accumulator HV indicator | H83: =IF(COUNTIF(H84:H92,"="&IncompleteText),IncompleteText,IF(COUNTIF(H84:H92,"="&ErrorText),ErrorText,OKText)) -> BLANK
A84: 高压指示器来源 Indicator source | H84: =IF(ISBLANK(G84),IncompleteText,OKText) -> BLANK
A85: 电压传感器绝缘电压 Galvanic Isolation (Vdc) | H85: =IF(G$84="车队自制电路 Self-designed",OKText,IF(ISBLANK(G85),IncompleteText,IF(G85>MaxTSVoltage,OKText,ErrorText))) -> BLANK
...

Sheet 预充电放电 PrechargeDischarge
A1: 状态 Status | B1: {=IF(SUM(COUNTIF(INDIRECT({"$F$2","$L$2","$R$2"}),"="&IncompleteText)),IncompleteText,IF(SUM(COUNTIF(INDIRECT({"$F$2","$L$2","$R$2"}),"="&ErrorText)),ErrorText,OKText))} -> BLANK
A2: 预充电回路 Precharge | F2: =IF(COUNTIF(F3:F19,"="&IncompleteText),IncompleteText,IF(COUNTIF(F3:F19,"="&ErrorText),ErrorText,OKText)) -> BLANK | G2: 放电回路 Discharge | L2: =IF(COUNTIF(L3:L15,"="&IncompleteText),IncompleteText,IF(COUNTIF(L3:L15,"="&ErrorText),ErrorText,OKText)) -> BLANK | M2: TSMP | R2: =IF(COUNTIF(R3:R8,"="&IncompleteText),IncompleteText,IF(COUNTIF(R3:R8,"="&ErrorText),ErrorText,OKText)) -> BLANK | S2: 规则参考 Rules ref
A3: 电阻型号 Resistor Type | F3: =IF(ISBLANK(D3),IncompleteText,OKText) -> BLANK | G3: 电阻型号 Resistor Type | L3: =IF(ISBLANK(J3),IncompleteText,OKText) -> BLANK | M3: 电阻型号 Resistor Type | R3: =IF(ISBLANK(P3),IncompleteText,OKText) -> BLANK | S3: 第五章 6.7 第五章 5.9 第五章 5.7
A4: 并联数 # parallel | F4: =IF(ISBLANK(D4),IncompleteText,OKText) -> BLANK | G4: 并联数 # parallel | L4: =IF(ISBLANK(J4),IncompleteText,OKText) -> BLANK | M4: 并联数 # parallel | R4: =IF(ISBLANK(P4),IncompleteText,OKText) -> BLANK
A5: 串联数 # serial | F5: =IF(ISBLANK(D5),IncompleteText,OKText) -> BLANK | G5: 串联数 # serial | L5: =IF(ISBLANK(J5),IncompleteText,OKText) -> BLANK | M5: 串联数 # serial | R5: =IF(ISBLANK(P5),IncompleteText,OKText) -> BLANK
A6: 总阻值 Resistance | D6: =VLOOKUP(D3,ResistorsTable,3,)*D5/D4 -> #N/A | E6: Ohms | G6: 总阻值 Resistance | J6: =VLOOKUP(J3,ResistorsTable,3,)*J5/J4 -> #N/A | K6: Ohms | M6: 总阻值 Resistance | P6: =VLOOKUP(P3,ResistorsTable,3,)*P5/P4 -> #N/A | Q6: Ohms | R6: =IF(MaxTSVoltage<=200,IF(P6=5000,OKText,ErrorText),IF(MaxTSVoltage>400,IF(P6=15000,OKText,ErrorText),IF(P6=10000,OKText,ErrorText))) -> #N/A
A7: 额定功率 Cont power | D7: =VLOOKUP(D3,ResistorsTable,4,FALSE)*D4*D5 -> #N/A | E7: W | G7: 额定功率 Cont power | J7: =VLOOKUP(J3,ResistorsTable,4,FALSE)*J4*J5 -> #N/A | K7: W | L7: =IF(J7=0,IncompleteText,IF(J7>=J9,OKText,ErrorText)) -> #N/A | M7: 额定功率 Cont power | P7: =VLOOKUP(P3,ResistorsTable,4,FALSE)*P5*P4 -> #N/A | Q7: W | R7: =IF(P7<P9,ErrorText,OKText) -> #N/A
A8: 瞬时持续功率(5s) Power @ 5s | E8: W | F8: =IF(ISBLANK(D8),IncompleteText,OKText) -> BLANK | G8: 额定电压 Rated Voltage | J8: =VLOOKUP(J3,ResistorsTable,2,FALSE)*J5 -> #N/A | K8: Vdc | L8: =IF(J8=0,IncompleteText,IF(J8<MaxTSVoltage,ErrorText,OKText)) -> #N/A | M8: 额定电压 Rated Voltage | P8: =VLOOKUP(P3,ResistorsTable,2,FALSE)*P5 -> #N/A | Q8: V | R8: =IF(P8<MaxTSVoltage,ErrorText,OKText) -> #N/A
A9: 额定电压 Rated Voltage | D9: =VLOOKUP(D3,ResistorsTable,2,FALSE)*D5 -> #N/A | E9: Vdc | F9: =IF(D9<MaxTSVoltage,ErrorText,OKText) -> #N/A | G9: 放电峰值功率 Peak Power | J9: =MaxTSVoltage^2/DischargeRes -> #N/A | K9: W | M9: 短路功率 Power if short circuit | P9: =MaxTSVoltage^2/(2*P6) -> #N/A | Q9: W | R9: =IF(ISNA(P9),IncompleteText,IF((P9/2)<=P7,OKText,ErrorText)) -> BLANK
A10: 总线电容 Bus Capacitance | E10: mF | F10: =IF(ISBLANK(BusCap),IncompleteText,OKText) -> BLANK | G10: 放电峰值电流 Peak Current | J10: =MaxTSVoltage/DischargeRes -> #N/A | K10: A
A11: 充电截止条件 End of precharge | E11: % | F11: =IF(ISBLANK(D11),IncompleteText,IF(D11>=95,OKText,ErrorText)) -> BLANK | G11: 放电时间 Discharge time | J11: =-LN(60/MaxTSVoltage)*DischargeRes*(BusCap/1000) -> #DIV/0! | K11: s
A12: 峰值功率 Peak Power | D12: =MaxTSVoltage^2/PrechargeRes -> #N/A | E12: W | G12: 放电继电器 Relay | L12: =IF(ISBLANK(J12),IncompleteText,OKText) -> BLANK
A13: 峰值电流 Peak Current | D13: =MaxTSVoltage/PrechargeRes -> #N/A | E13: A | G13: 继电器触点额定电压 Contacts rated volatge | J13: =VLOOKUP(J12,ContactorsTable,2,FALSE) -> #N/A | K13: V | L13: =IF(J13<MaxTSVoltage,ErrorText,OKText) -> #N/A
A14: 充电到95% Time to 95% | D14: =-LN(0.05)*(BusCap/1000)*PrechargeRes -> #N/A | E14: sec | G14: 继电器触点额定电流 Contact rated current | J14: =VLOOKUP(J12,ContactorsTable,3,FALSE) -> #N/A | K14: A | L14: =IF(J14<J10,ErrorText,OKText) -> #N/A
A15: 预充电能量95% Energy on res to 95% | D15: =MaxTSVoltage^2*(BusCap/1000)/2*(1-EXP(-D14*2/(PrechargeRes*(BusCap/1000)))) -> #N/A | E15: J | G15: 继电器断电状态 Normal State | J15: =VLOOKUP(J12,ContactorsTable,5,FALSE) -> #N/A | L15: =IF(J15<>"NC",ErrorText,OKText) -> #N/A
A16: 平均功率 average power | D16: =D15/D14 -> #N/A | E16: W
A17: 预充电继电器 Relay | F17: =IF(ISBLANK(D17),IncompleteText,OKText) -> BLANK
A18: 继电器触点额定电压 Contacts rated volatge | D18: =VLOOKUP(D17,ContactorsTable,2,FALSE) -> #N/A | E18: Vdc | F18: =IF(D18<MaxTSVoltage,ErrorText,OKText) -> #N/A
A19: 继电器触点额定电流 Contact rated current | D19: =VLOOKUP(D17,ContactorsTable,3,FALSE) -> #N/A | E19: A | F19: =IF(D19<D13,ErrorText,OKText) -> #N/A
A21: 补充说明 Additional Comments

Sheet 充电 Charging
A1: 状态 Status | B1: {=IF(SUM(COUNTIF(INDIRECT({"$F$2","$H$31","$Q$31","$Z$31"}),"="&IncompleteText)),IncompleteText,IF(SUM(COUNTIF(INDIRECT({"$F$2","$H$31","$Q$31","$Z$31"}),"="&ErrorText)),ErrorText,OKText))} -> BLANK
A2: 充电机 Charger | F2: =IF(COUNTIF(F3:F10,"="&IncompleteText),IncompleteText,IF(COUNTIF(F3:F10,"="&ErrorText),ErrorText,OKText)) -> BLANK | H2: 补充说明 Additioanl Comments
A3: 制造商 Make | F3: =IF(ISBLANK(D3),IncompleteText,OKText) -> BLANK
A4: 型号 Type | F4: =IF(ISBLANK(D4),IncompleteText,OKText) -> BLANK
A5: 说明书超链接 Datasheet link | F5: =IF(ISBLANK(D5),IncompleteText,OKText) -> BLANK
A6: 输入电压(市电或工业电) Input Voltage | E6: Vac | F6: =IF(ISBLANK(D6),IncompleteText,OKText) -> BLANK
A7: 输入电流 Input Current | E7: A | F7: =IF(ISBLANK(D7),IncompleteText,OKText) -> BLANK
A8: 输出电压(定值或范围) Output Voltage | E8: V | F8: =IF(ISBLANK(D8),IncompleteText,OKText) -> BLANK
A9: 输出电流 Output Current | E9: A | F9: =IF(ISBLANK(D9),IncompleteText,OKText) -> BLANK
A10: 充电机额定功率 Rated Power | E10: kW | F10: =IF(ISBLANK(D10),IncompleteText,OKText) -> BLANK
J12: 充电安全回路 Charging Shutdown Circuit | S12: 电池箱小推车 Accumulator Handcart
A31: 充电驱动系统回路 Charging Tractive System Schematic | H31: =IF(COUNTIF(H33:H38,"="&IncompleteText),IncompleteText,IF(COUNTIF(H33:H38,"="&ErrorText),ErrorText,OKText)) -> BLANK | J31: 充电安全回路 Charging Shutdown Circuit | Q31: =IF(COUNTIF(Q33:Q38,"="&IncompleteText),IncompleteText,IF(COUNTIF(Q33:Q38,"="&ErrorText),ErrorText,OKText)) -> BLANK | S31: 电池箱小推车 Accumulator Handcart | Z31: =IF(COUNTIF(Z33:Z34,"="&IncompleteText),IncompleteText,IF(COUNTIF(Z33:Z34,"="&ErrorText),ErrorText,OKText)) -> BLANK
A32: 规则参考 Rules Ref | J32: 规则参考 Rules Ref | S32: 规则参考 Rules Ref
C33: 主保险丝（直流） Main Fuse on DC bus | H33: =IF(ISBLANK(G33),IncompleteText,IF(G33,OKText,ErrorText)) -> BLANK | L33: IMD控制的继电器 IMD Controlled powerstage | Q33: =IF(ISBLANK(P33),IncompleteText,IF(P33,OKText,ErrorText)) -> BLANK | S33: 第五章 9.4.6 | U33: 垂直防火墙及高度要求满足 Firewall Height and coverage | Z33: =IF(ISBLANK(Y33),IncompleteText,IF(Y33,OKText,ErrorText)) -> BLANK
C34: 接插件及制造商/型号 Connector with Make/Type | H34: =IF(ISBLANK(G34),IncompleteText,IF(G34,OKText,ErrorText)) -> BLANK | L34: AMS控制的继电器 AMS Controlled powerstage | Q34: =IF(ISBLANK(P34),IncompleteText,IF(P34,OKText,ErrorText)) -> BLANK | S34: 第五章 9.4.8 | U34: 防冲击措施 Anti-shock | Z34: =IF(ISBLANK(Y34),IncompleteText,IF(Y34,OKText,ErrorText)) -> BLANK
C35: 标注线径 Wire Gauge | H35: =IF(ISBLANK(G35),IncompleteText,IF(G35,OKText,ErrorText)) -> BLANK | L35: 充电急停开关 Shutdown buttons | Q35: =IF(ISBLANK(P35),IncompleteText,IF(P35,OKText,ErrorText)) -> BLANK | S35: 补充说明 Additional Comments
C36: IMD | H36: =IF(ISBLANK(G36),IncompleteText,IF(G36,OKText,ErrorText)) -> BLANK | L36: AIRs线圈 AIRs coils | Q36: =IF(ISBLANK(P36),IncompleteText,IF(P36,OKText,ErrorText)) -> BLANK
C37: AIRs | H37: =IF(ISBLANK(G37),IncompleteText,IF(G37,OKText,ErrorText)) -> BLANK | L37: 充电接插件互锁 Interlock of charging connector | Q37: =IF(ISBLANK(P37),IncompleteText,IF(P37,OKText,ErrorText)) -> BLANK
C38: TSMPs | H38: =IF(ISBLANK(G38),IncompleteText,IF(G38,OKText,ErrorText)) -> BLANK | L38: 充电安全的其他控制继电器(安全回路以外) Other powerstages | Q38: =IF(ISBLANK(P38),IncompleteText,IF(P38,OKText,ErrorText)) -> BLANK
A39: 补充说明 Additional Comments | J39: 补充说明 Additional Comments

Sheet 安全系统 Shutdown circuit
A1: 状态 Status | B1: {=IF(SUM(COUNTIF(INDIRECT({"$F$2","$M$2","$K$36","$W$36","$K$94","$Z$8","$W$96"}),"="&IncompleteText)),IncompleteText,IF(SUM(COUNTIF(INDIRECT({"$F$2","$M$2","$K$36","$W$36","$K$94","$Z$8","$W$96"}),"="&ErrorText)),ErrorText,OKText))} -> BLANK
A2: IMD | F2: =IF(COUNTIF(F4:F8,"="&IncompleteText),IncompleteText,IF(COUNTIF(F4:F8,"="&ErrorText),ErrorText,OKText)) -> BLANK | H2: BSPD | M2: =IF(COUNTIF(M4:M8,"="&IncompleteText),IncompleteText,IF(COUNTIF(M4:M8,"="&ErrorText),ErrorText,OKText)) -> BLANK
A3: 规则参考 Rules Ref | D3: 第五章 7.4 | H3: 规则参考 Rules Ref | K3: 第五章 7.5
A4: 制造商 Make | F4: =IF(ISBLANK(D4),IncompleteText,OKText) -> BLANK | H4: 电流传感器型号 Current Sensor Type | M4: =IF(ISBLANK(K4),IncompleteText,OKText) -> BLANK
A5: 触发阈值 Threshold | E5: kΩ | F5: =IF(ISBLANK(D5),IncompleteText,IF(D5<(MaxTSVoltage*0.5),ErrorText,OKText)) -> BLANK | H5: 电流传感器说明书链接 Current Sensor datasheet | M5: =IF(ISBLANK(K5),IncompleteText,OKText) -> BLANK
A6: 接地线1接地位置 Location of grounding measurement 1 | F6: =IF(ISBLANK(D6),IncompleteText,OKText) -> BLANK | H6: 设定阈值电流(驱动系统) Trip Current (TS) | L6: A | M6: =IF(ISBLANK(K6),IncompleteText,IF(K6>(5000/MaxTSVoltage),ErrorText,OKText)) -> BLANK
A7: 接地线2接地位置 Location of grounding measurement 2 | F7: =IF(ISBLANK(D7),IncompleteText,OKText) -> BLANK | H7: 传感器输出@阈值电流 Sensor Output@Trip current | L7: V | M7: =IF(ISBLANK(K7),IncompleteText,OKText) -> BLANK
A8: 驱动系统测点物理位置 | F8: =IF(ISBLANK(D8),IncompleteText,OKText) -> BLANK | H8: 传感器测量精度@阈值电流 Accuracy@Trip current | L8: A | M8: =IF(ISBLANK(K8),IncompleteText,OKText) -> BLANK | Y8: TSAL | Z8: {=IF(SUM(COUNTIF(INDIRECT({"$AI$36","$AI$50","$AI$56","$AU$36","$AU$77","$BG$77"}),"="&IncompleteText)),IncompleteText,IF(SUM(COUNTIF(INDIRECT({"$AI$36","$AI$50","$AI$56","$AU$36","$AU$77","$BG$77"}),"="&ErrorText)),ErrorText,OKText))} -> OK
Y9: TSAL测量点分布 | AK9: TSAL红灯-电压测量原理图 采购传感器无需填写 允许利用右侧补充说明-1附上不便于单幅展示的原理图（比如存在多个电机控制器壳体） TSAL Red - Schematic on voltage measurement N/A if use purchased sensor Fill the cell on the right Additional comment-1 for multi-page schematics (mutiple motor controller enclosure for example)
A10: 安全回路原理图 Shutdown Circuit Schematic | M10: BSPD原理图 BSPD schematic
Y35: TSAL - 分布 TSAL component distribuition | AI35: =IF(COUNTIF(AI37:AI41,"="&IncompleteText),IncompleteText,IF(COUNTIF(AI37:AI41,"="&ErrorText),ErrorText,OKText)) -> BLANK | AK35: TSAL红灯部分电路 TSAL circuit on Red Lights | AU35: =IF(COUNTIF(AU37:AU48,"="&IncompleteText),IncompleteText,IF(COUNTIF(AU37:AU48,"="&ErrorText),ErrorText,OKText)) -> BLANK
A36: 安全回路原理图 Shutdown Circuit Schematic | K36: =IF(COUNTIF(K38:K62,"="&IncompleteText),IncompleteText,IF(COUNTIF(K38:K62,"="&ErrorText),ErrorText,OKText)) -> BLANK | M36: BSPD原理图 BSPD schematic | W36: =IF(COUNTIF(W38:W41,"="&IncompleteText),IncompleteText,IF(COUNTIF(W38:W41,"="&ErrorText),ErrorText,OKText)) -> BLANK | AW36: 补充说明-2 additional comment 2
A37: 规则参考 | Y37: 继电器检测电路必须位于电池箱内部,禁止将辅助触点/电压测量线引出 TSAL relay status detecion must be within the Accumulator, aux contacts/aux volatge not wiring out | AI37: =IF(ISBLANK(AH37),IncompleteText,IF(AH37,OKText,ErrorText)) -> BLANK | AK37: 电压检测器件来源 Source of voltage sensors | AU37: =IF(ISBLANK(AT37),IncompleteText,OKText) -> BLANK
A38: 第五章 7.2.2 | C38: LVMS | K38: =IF(ISBLANK(J38),IncompleteText,IF(J38,OKText,ErrorText)) -> BLANK | M38: BSPD电流传感器输入短路/短路保护 BSPD Current Sensor input open/short protection | W38: =IF(ISBLANK(V38),IncompleteText,IF(V38,OKText,ErrorText)) -> BLANK | Y38: 注明各个部分位于的实际壳体及系统 Physical locations of all TS components enclosures | AI38: =IF(ISBLANK(AH38),IncompleteText,IF(AH38,OKText,ErrorText)) -> BLANK | AK38: 电压传感器绝缘电压 Galvanic Isolation level (V) | AU38: =IF(AT$37="车队自制原理",OKText,IF(ISBLANK(AT38),IncompleteText,IF(AT38,OKText,ErrorText))) -> BLANK
A39: 第五章 7.2.3 | C39: TSMS | K39: =IF(ISBLANK(J39),IncompleteText,IF(J39,OKText,ErrorText)) -> BLANK | M39: BSPD制动传感器输入短路/短路保护 BSPD Brake Sensor input open/short protection | W39: =IF(ISBLANK(V39),IncompleteText,IF(V39,OKText,ErrorText)) -> BLANK | Y39: 壳体外信号线注明信号类型(数字,模拟) The type of signal outside enclosures (digital , analog) | AI39: =IF(ISBLANK(AH39),IncompleteText,IF(AH39,OKText,ErrorText)) -> BLANK | AK39: 电压传感器说明书超链接 Sensor datasheet | AU39: =IF(AT$37="车队自制原理",OKText,IF(ISBLANK(AT39),IncompleteText,IF(AT39,OKText,ErrorText))) -> BLANK
A40: 第五章 7.3.3 | C40: 2x侧面急停 2x shutdown buttons on both sides | K40: =IF(ISBLANK(J40),IncompleteText,IF(J40,OKText,ErrorText)) -> BLANK | M40: 自动复位计时部分符合规则要求 Auto-reset timer settings | W40: =IF(ISBLANK(V40),IncompleteText,IF(V40,OKText,ErrorText)) -> BLANK | Y40: 注明锁存逻辑的位置 Position of the latching logic | AI40: =IF(ISBLANK(AH40),IncompleteText,IF(AH40,OKText,ErrorText)) -> BLANK | AK40: 原理图清晰可读 Schematic readable | AU40: =IF(AT$37="购买传感器",OKText,IF(ISBLANK(AT40),IncompleteText,IF(AT40,OKText,ErrorText))) -> BLANK
A41: 第五章 7.3.4 | C41: 驾驶舱急停 Cockpit shutdown button | K41: =IF(ISBLANK(J41),IncompleteText,IF(J41,OKText,ErrorText)) -> BLANK | M41: 安全回路继电器 Shutdown circuit powerstage | W41: =IF(ISBLANK(V41),IncompleteText,IF(V41,OKText,ErrorText)) -> BLANK | Y41: 禁止在壳体外出现无过流保护的驱动系统采样线段落（注明保险丝的物理位置）No TS volatge detection wires outside enclosures if not protected by fuses | AI41: =IF(ISBLANK(AH41),IncompleteText,IF(AH41,OKText,ErrorText)) -> BLANK | AK41: 标注所有的驱动系统元器件（包括接插件)的型号和额定电压 Type and rated volatge of all TS components | AU41: =IF(AT$37="购买传感器",OKText,IF(ISBLANK(AT41),IncompleteText,IF(AT41,OKText,ErrorText))) -> BLANK
A42: 第二章 7.3 | C42: 制动超程开关 Brake Over Travel Switch (BOTS) | K42: =IF(ISBLANK(J42),IncompleteText,IF(J42,OKText,ErrorText)) -> BLANK | M42: 补充说明 Additional Comments | V42: 规则参考 Rules Ref | Y42: 补充说明 Additional Comments | AH42: 规则参考 Rules ref | AK42: 隔离器件的说明书超链接 Datasheet of galvanic devices | AU42: =IF(AT36="购买传感器",OKText,IF(ISBLANK(AT42),IncompleteText,IF(ISBLANK(AT42),ErrorText,OKText))) -> BLANK
A43: 第二章 12.5 | C43: 惯性开关 Inertia Switch | K43: =IF(ISBLANK(J43),IncompleteText,IF(J43,OKText,ErrorText)) -> BLANK | V43: 第五章 7.5 | AH43: 第五章 5.10.4 | AK43: 标注驱动系统电阻的额定功率(如果有) Rated power of TS resistors, if used | AU43: =IF(AT$37="购买传感器",OKText,IF(ISBLANK(AT43),IncompleteText,IF(AT43,OKText,ErrorText))) -> BLANK
A44: 第五章 7.1.6 | C44: 电池管理系统控制的继电器 AMS controlled powerstage | K44: =IF(ISBLANK(J44),IncompleteText,IF(J44,OKText,ErrorText)) -> BLANK | AK44: 驱动系统电路保险丝型号 Type of TS fuses | AU44: =IF(ISBLANK(AT44),IncompleteText,IF(ISBLANK(AT44),ErrorText,OKText)) -> BLANK
A45: 第五章 7.1.6 | C45: IMD控制的继电器 IMD controlled powerstage | K45: =IF(ISBLANK(J45),IncompleteText,IF(J45,OKText,ErrorText)) -> BLANK | AK45: 保险丝额定电压 Rated Voltage of the fuse | AT45: =VLOOKUP(AT44,FuseTable,2,FALSE) -> #N/A | AU45: =IF(ISNA(AT45),IncompleteText,OKText) -> BLANK
A46: 第五章 7.5 | C46: BSPD | K46: =IF(ISBLANK(J46),IncompleteText,IF(J46,OKText,ErrorText)) -> BLANK | AK46: 如果阈值是固定的，给出计算过程（右侧补充说明-2）IF volatge threshold is not adjustable, please give the cacualtion on additional comment -2 | AU46: =IF(ISBLANK(AT46),IncompleteText,IF(AT46,OKText,ErrorText)) -> BLANK
A47: 第五章 5.5.10 | C47: HVD互锁 HVD Interlock | K47: =IF(ISBLANK(J47),IncompleteText,IF(J47,OKText,ErrorText)) -> BLANK | AK47: 电压检测结果之间不存在任何可靠性检查 No plausibility check among volatage detections | AU47: =IF(ISBLANK(AT47),IncompleteText,IF(AT47,OKText,ErrorText)) -> BLANK
A48: 第五章 7.1.9 | C48: IMD, AMS, BSPD的继电器是相互独立的 IMD,AMS and BSPD have independent powerstages | K48: =IF(ISBLANK(J48),IncompleteText,IF(J48,OKText,ErrorText)) -> BLANK | AK48: 闪烁频率设定电路 Flashing frequency settings | AU48: =IF(ISBLANK(AT48),IncompleteText,IF(AT48,OKText,ErrorText)) -> BLANK
A49: 第五章 5.4.3 | C49: 轮边互锁 Outboard wheel motor interlocks (if exists) | K49: =IF(ISBLANK(J49),IncompleteText,IF(J49,OKText,ErrorText)) -> BLANK | Y49: TSAL - 总体要求 General | AI49: =IF(COUNTIF(AI51:AI52,"="&IncompleteText),IncompleteText,IF(COUNTIF(AI51:AI52,"="&ErrorText),ErrorText,OKText)) -> BLANK
A50: 第二章 12.7 | C50: 低压电池 LVS battery | K50: =IF(ISBLANK(J50),IncompleteText,IF(J50,OKText,ErrorText)) -> BLANK | Y50: 所有的原理图合并后需要满足下述要求 The schematics jointly shows | AK50: TSAL绿灯-电压检测及继电器状态检测 TSAL Green - Volatge detection and relay status detections | AW50: TSAL通用-锁存逻辑 TSAL general - latching logic
C51: 低压系统保险丝 LVS fuse | K51: =IF(ISBLANK(J51),IncompleteText,IF(J51,OKText,ErrorText)) -> BLANK | Y51: 所有逻辑实现必须是不可编程的纯硬件电路 Non-programmable logic based on hardwares | AI51: =IF(ISBLANK(AH51),IncompleteText,IF(AH51,OKText,ErrorText)) -> BLANK
C52: 标注线径 Wiring gauge | K52: =IF(ISBLANK(J52),IncompleteText,IF(J52,OKText,ErrorText)) -> BLANK | Y52: 绿灯和红灯必须可以同时亮起（禁止电路存在二元选择的逻辑） | AI52: =IF(ISBLANK(AH52),IncompleteText,IF(AH52,OKText,ErrorText)) -> BLANK
A53: 第五章 6.7.3 | C53: 预充电继电器 Precharge relay coil | K53: =IF(ISBLANK(J53),IncompleteText,IF(J53,OKText,ErrorText)) -> BLANK
A54: 第五章 7.1.3 | C54: 主正线圈 AIR+ coil | K54: =IF(ISBLANK(J54),IncompleteText,IF(J54,OKText,ErrorText)) -> BLANK
C55: 主负线圈 AIR- coil | K55: =IF(ISBLANK(J55),IncompleteText,IF(J55,OKText,ErrorText)) -> BLANK | Y55: TSAL - 真值表自查 Truth Table | AI55: =IF(COUNTIF(AI57:AI58,"="&IncompleteText),IncompleteText,IF(COUNTIF(AI57:AI58,"="&ErrorText),ErrorText,OKText)) -> BLANK
C56: 放电继电器线圈 Discharge relay coil | K56: =IF(ISBLANK(J56),IncompleteText,IF(J56,OKText,ErrorText)) -> BLANK | Y56: 请根据车队的设计填写TSAL的状态，在LVS供电的情况下 Based on TSAL design, with LVS power on
A57: 第五章 7.1.4 | C57: TSMS是最后一个开关(互锁除外) TSMS is the last switch (except for interlocks) | K57: =IF(ISBLANK(J57),IncompleteText,IF(J57,OKText,ErrorText)) -> BLANK | Y57: 场景 Scenerios | AG57: 绿灯 Green | AH57: 红灯 Red
C58: LVMS是第一个开关 LVMS is the first switch | K58: =IF(ISBLANK(J58),IncompleteText,IF(J58,OKText,ErrorText)) -> BLANK | Y58: HVD移除就进行上电，预充电开始 Start Precharge without HVD on | AI58: =IF(OR(ISBLANK(AG58),ISBLANK(AH58)),IncompleteText,IF(AND(AH58="熄灭 OFF",AG58="熄灭 OFF"),OKText,ErrorText)) -> BLANK
C59: 使用通用的原理图符号 Proper electrical schematic symbols | K59: =IF(ISBLANK(J59),IncompleteText,IF(J59,OKText,ErrorText)) -> BLANK | Y59: 绿灯电压检测线开路，但是未开始进行上电操作 Green light voltage detection open, but not activite TS | AI59: =IF(OR(ISBLANK(AG59),ISBLANK(AH59)),IncompleteText,IF(AND(AG59="常亮 ON",AH59="熄灭 OFF"),OKText,ErrorText)) -> BLANK
C60: 图片高清 Readable with zooming | K60: =IF(ISBLANK(J60),IncompleteText,IF(J60,OKText,ErrorText)) -> BLANK | Y60: 从高压壳体中引出，传输测量结果的低压线开路，但是未开始上电 LVS signal presenting status from TS enclosres open, but not activite TS | AI60: =IF(OR(ISBLANK(AG60),ISBLANK(AH60)),IncompleteText,IF(AND(AG60="常亮 ON",AH60="熄灭 OFF"),OKText,ErrorText)) -> BLANK
A61: 第五章 5.11.2 | C61: 闭合任何一个开关都不能（再）激活驱动系统 Closing any switch will not (re)activate TS | K61: =IF(ISBLANK(J61),IncompleteText,IF(J61,OKText,ErrorText)) -> BLANK | Y61: 未上电时，由于快速推动车辆，电机控制器出现了超过60V的浪涌电压 When AIRs are open there are >60V volatge on motor controllers because of pushing the car too fast | AI61: =IF(OR(ISBLANK(AG61),ISBLANK(AH61)),IncompleteText,IF(AND(AG61="常亮 ON",AH61="闪烁 Flashing"),OKText,ErrorText)) -> BLANK
A62: 第五章 5.5.10 | C62: 高压壳体外的高压接插件互锁 Interlocks on TS connectors outside of an enclosure | K62: =IF(ISBLANK(J62),IncompleteText,IF(J62,OKText,ErrorText)) -> BLANK | Y62: 电机控制器内高压检测线开路，开始上电 Activate TS when voltage detection in Motor controller open | AI62: =IF(OR(ISBLANK(AG62),ISBLANK(AH62)),IncompleteText,IF(AND(AH62="熄灭 OFF",AG62="熄灭 OFF"),OKText,ErrorText)) -> BLANK
A63: 补充说明 Additional Comments | J63: 规则参考 Rules Ref | Y63: ·未上电时，传输绿灯状态的低压SCS信号出现短路或者开路 When AIRs are open, the LVS SCS signal with green light information is short or open | AI63: =IF(OR(ISBLANK(AG63),ISBLANK(AH63)),IncompleteText,IF(AND(AH63="熄灭 OFF",AG63="熄灭 OFF"),OKText,ErrorText)) -> BLANK
J64: 第五章 7.1
...

Sheet 扭矩指令 Torque Security
A1: 状态 status | B1: {=IF(SUM(COUNTIF(INDIRECT({"$F$2","$F$3","$F$4","$S$6"}),"="&IncompleteText)),IncompleteText,IF(SUM(COUNTIF(INDIRECT({"$F$2","$F$3","$F$4","$S$6"}),"="&ErrorText)),ErrorText,OKText))} -> BLANK
A2: APPS传感器输出类型 Type of APPS sensor output | F2: =IF(ISBLANK(E2),IncompleteText,OKText) -> BLANK | H2: 影响扭矩输出路径检查 Torque Control Path Security Checks | S2: =IF(COUNTIF(S6:S11,"="&IncompleteText),IncompleteText,IF(COUNTIF(S6:S11,"="&ErrorText),ErrorText,OKText)) -> BLANK
A3: APPS传感器说明书超连接 APPS datasheet | F3: =IF(ISBLANK(E3),IncompleteText,OKText) -> BLANK
A4: APPS 传感器传递函数 APPS transfer function | F4: =IF(E2="数字 digital",OKText,IF(COUNTIF(F7:F13,"="&IncompleteText),IncompleteText,IF(COUNTIF(F7:F13,"="&ErrorText),ErrorText,OKText))) -> BLANK | H4: 起点 Source device | J4: 终点 Destination device | L4: 通讯方式 communication | M4: 冗余保护 Redundant | N4: 超程保护 Out of range | O4: 相关性保护 Correlation | P4: 校验和 Checksum | Q4: 超时保护 Timeout | R4: 其他 Other | T4: 补充说明 Additional comment
A5: 规则参考 Rules Ref | C5: 第二章 12.8.6
A6: 传感器行程 Sensor travel | B6: APPS1输出Output [V] | D6: APPS2输出 Output[V] | H6: APPS | S6: =IF(COUNTBLANK(J6:L6)>1,IncompleteText,OKText) -> BLANK
A7: 0 | F7: =IF(OR(ISBLANK(B7),ISBLANK(D7)),IncompleteText,OKText) -> BLANK | H7: =IF(ISBLANK(J6),"",J6) | S7: =IF(ISBLANK(J7),"",IF(ISBLANK(L7),IncompleteText,OKText))
A8: 0.2 | F8: =IF(OR(ISBLANK(B8),ISBLANK(D8)),IncompleteText,IF(OR(AND(_xlfn.XOR(B8<D8,B7<D7),B7<>D7),B8=D8),ErrorText,OKText)) -> BLANK | H8: =IF(ISBLANK(J7),"",J7) | S8: =IF(ISBLANK(J8),"",IF(ISBLANK(L8),IncompleteText,OKText))
A9: 0.4 | F9: =IF(OR(ISBLANK(B9),ISBLANK(D9)),IncompleteText,IF(OR(_xlfn.XOR(B9<D9,B8<D8),B9=D9),ErrorText,OKText)) -> BLANK | H9: =IF(ISBLANK(J8),"",J8) | S9: =IF(ISBLANK(J9),"",IF(ISBLANK(L9),IncompleteText,OKText))
A10: 0.6 | F10: =IF(OR(ISBLANK(B10),ISBLANK(D10)),IncompleteText,IF(OR(_xlfn.XOR(B10<D10,B9<D9),B10=D10),ErrorText,OKText)) -> BLANK | H10: =IF(ISBLANK(J9),"",J9) | S10: =IF(ISBLANK(J10),"",IF(ISBLANK(L10),IncompleteText,OKText))
A11: 0.8 | F11: =IF(OR(ISBLANK(B11),ISBLANK(D11)),IncompleteText,IF(OR(_xlfn.XOR(B11<D11,B10<D10),B11=D11),ErrorText,OKText)) -> BLANK | H11: =IF(ISBLANK(J10),"",J10) | S11: =IF(ISBLANK(J11),"",IF(ISBLANK(L11),IncompleteText,OKText))
A12: 1 | F12: =IF(OR(ISBLANK(B12),ISBLANK(D12)),IncompleteText,IF(OR(_xlfn.XOR(B12<D12,B11<D11),B12=D12),ErrorText,OKText)) -> BLANK
A13: 除0%行程处以外，禁止传递函数相交 No crossing except at 0% | F13: =IF(ISBLANK(E13),IncompleteText,IF(E13,OKText,FALSE)) -> BLANK

Sheet 其他 Others
A1: 状态 Status | B1: {=IF(SUM(COUNTIF(INDIRECT({"$F$2","$L$2","$H$28","$Q$28","$Z$8"}),"="&IncompleteText)),IncompleteText,IF(SUM(COUNTIF(INDIRECT({"$F$2","$L$2","$H$28","$Q$28","$Z$8"}),"="&ErrorText)),ErrorText,OKText))} -> BLANK
A2: 电机控制器 Motor Controller | F2: =IF(COUNTIF(F3:F7,"="&IncompleteText),IncompleteText,IF(COUNTIF(F3:F7,"="&ErrorText),ErrorText,OKText)) -> BLANK | G2: 电机 Motors | L2: =IF(COUNTIF(L3:L5,"="&IncompleteText),IncompleteText,IF(COUNTIF(L3:L5,"="&ErrorText),ErrorText,OKText)) -> BLANK
A3: 制造商 Make | F3: =IF(ISBLANK(D3),IncompleteText,OKText) -> BLANK | G3: 制造商 Make | L3: =IF(ISBLANK(J3),IncompleteText,OKText) -> BLANK
A4: 型号 Type | F4: =IF(ISBLANK(D4),IncompleteText,OKText) -> BLANK | G4: 型号 Type | L4: =IF(ISBLANK(J4),IncompleteText,OKText) -> BLANK
A5: 说明书超连接 Datasheet | F5: =IF(ISBLANK(D5),IncompleteText,OKText) -> BLANK | G5: 说明书超链接 Datasheet hyperlink | L5: =IF(ISBLANK(J5),IncompleteText,OKText) -> BLANK
A6: 高低压系统绝缘电压 Galvanic Isolation voltage | E6: V | F6: =IF(ISBLANK(D6),IncompleteText,IF(D6<MaxTSVoltage,ErrorText,OKText)) -> BLANK
S8: 低压电池 LVS Battery | Z8: {=IF(SUM(COUNTIF(INDIRECT({"其他!$Z$28","其他!$Z$30","其他!$AI$28"}),"="&IncompleteText)),IncompleteText,IF(SUM(COUNTIF(INDIRECT({"其他!$Z$28","其他!$Z$30","其他!$AI$28"}),"="&ErrorText)),ErrorText,OKText))} -> #VALUE! | AK8: 补充说明 Additional comments
A9: 能量计安装位置CAD/渲染图 Energy Meter Location | J9: HVD位置及与包络面的关系 HVD location and its relations with the envelop | S9: 低压电池位置CAD/渲染图 LVS Battery Location | AB9: 低压电池组温度采样触点位置 Location of LVS battery temperature measurement
A28: 能量计安装位置CAD/渲染图 Energy Meter Location | H28: =IF(COUNTIF(H29,"="&IncompleteText),IncompleteText,IF(COUNTIF(H29,"="&ErrorText),ErrorText,OKText)) -> BLANK | J28: HVD安装位置CAD/渲染图 HVD Location CAD/renderings | Q28: =IF(COUNTIF(Q29,"="&IncompleteText),IncompleteText,IF(COUNTIF(Q29,"="&ErrorText),ErrorText,OKText)) -> BLANK | S28: 低压电池位置CAD/渲染图 LVS Battery Location | Z28: =IF(COUNTIF(Z29,"="&IncompleteText),IncompleteText,IF(COUNTIF(Z29,"="&ErrorText),ErrorText,OKText)) -> BLANK | AB28: 锂电池低压电池电芯电压温度采样 | AI28: =IF(Y32="其他锂电池 Other Li-ion",IF(COUNTIF(AI29:AI36,"="&IncompleteText),IncompleteText,IF(COUNTIF(AI29:AI36,"="&ErrorText),ErrorText,OKText)),OKText) -> OK
A29: 能量计位置 Location of Energy Meter | H29: =IF(ISBLANK(G29),IncompleteText,IF(G29,OKText,ErrorText)) -> BLANK | J29: HVD位于包络面内 HVD inside rollover envelop | Q29: =IF(ISBLANK(P29),IncompleteText,IF(P29,OKText,ErrorText)) -> BLANK | S29: 低压电池布置位置符合规则要求 Location Rules complicant | Z29: =IF(ISBLANK(Y29),IncompleteText,IF(Y29,OKText,ErrorText)) -> BLANK | AB29: 低压电池管理系统来源 LVS BMS source | AI29: =IF(ISBLANK(AH29),IncompleteText,OKText) -> BLANK
A30: 补充说明 Additional Comment | J30: 补充说明 Additional Comment | S30: 低压电池说明 LVS Battery | Z30: =IF(COUNTIF(Z31:Z40,"="&IncompleteText),IncompleteText,IF(COUNTIF(Z31:Z40,"="&ErrorText),ErrorText,OKText)) -> BLANK | AB30: 低压电池管理系统型号 BMS Type number | AI30: =IF(AH$29="车队自制",OKText,IF(ISBLANK(AH30),IncompleteText,OKText)) -> BLANK
S31: 低压电池制造方式 Source of LVS Battery | Z31: =IF(ISBLANK(Y31),IncompleteText,OKText) -> BLANK | AB31: 低压电池管理系统说明书超链接 Datasheet hyperlink | AI31: =IF(AH$29="车队自制",OKText,IF(ISBLANK(AH31),IncompleteText,OKText)) -> BLANK
S32: 电池电芯化学类型 Chemical type of cells | Y32: 磷酸铁锂 LiFePO4 | Z32: =IF(ISBLANK(Y32),IncompleteText,IF(Y32="非锂电池",IF(Z33=OKText,OKText,IncompleteText),OKText)) -> OK | AB32: 在右侧补充内容附上足够清晰的原理图 Schematics on the right additional comments | AI32: =IF(AH$29="供应商提供",OKText,IF(ISBLANK(AH32),IncompleteText,IF(AH32,OKText,ErrorText))) -> BLANK
S33: 说明具体化学类型 | Z33: =IF(Y32="非锂电池",IF(ISBLANK(Y33),IncompleteText,OKText),IF(ISBLANK(Y32),IncompleteText,OKText)) -> OK | AB33: 能够至少断开低压电池一极 Able disconnect one of the pole of the battery | AI33: =IF(ISBLANK(AH33),IncompleteText,IF(AH33,OKText,ErrorText)) -> BLANK
S34: 电芯/电池说明书超连接 Cell datasheet hyperlink | Z34: =IF(ISBLANK(Y34),IncompleteText,OKText) -> BLANK | AB34: 温度采样点数量占比 Cells measured by temp sensors [%] | AI34: =IF(ISBLANK(AH34),IncompleteText,IF(AH34>=30,OKText,ErrorText)) -> BLANK
S35: 串联数 # of serial | Z35: =IF(ISBLANK(Y35),IncompleteText,OKText) -> BLANK | AB35: 电压采样点数量占比 Cells measured by voltage sensors [%] | AI35: =IF(ISBLANK(AH35),IncompleteText,IF(AH35>=100,OKText,ErrorText)) -> BLANK
S36: 并联数 # of parallel | Z36: =IF(ISBLANK(Y36),IncompleteText,OKText) -> BLANK | AB36: 上位机通讯展示 Communication with an host interface | AI36: =IF(ISBLANK(AH36),IncompleteText,IF(AH36,OKText,ErrorText)) -> BLANK
S37: 电芯单体最大电压 Max cell voltage [V] | Z37: =IF(ISBLANK(Y37),IncompleteText,OKText) -> BLANK
S38: 电芯单体额定电压 Noimal cell voltage [V] | Z38: =IF(ISBLANK(Y38),IncompleteText,OKText) -> BLANK
S39: 电芯单体最大工作温度 Max cell operation temperature [C] | Z39: =IF(ISBLANK(Y39),IncompleteText,OKText) -> BLANK
S40: LVS最大电压 LVS battery pack max voltage [V] | Y40: =Y35*Y37 -> 0 | Z40: =IF(OR(ISBLANK(Y35),ISBLANK(Y37)),IncompleteText,IF(Y40<=60,OKText,ErrorText)) -> BLANK

Sheet 接地 Grounding
A1: 状态 Status | B1: {=IF(SUM(COUNTIF(INDIRECT({"$E$2","$I$2","$O$2"}),"="&IncompleteText)),IncompleteText,IF(SUM(COUNTIF(INDIRECT({"$E$2","$I$2","$O$2"}),"="&ErrorText)),ErrorText,OKText))} -> BLANK
A2: 表-1 基本部件接地要求 Grounding of primary parts | E2: =IF(COUNTIF(E3:E12,"="&IncompleteText),IncompleteText,IF(COUNTIF(E3:E12,"="&ErrorText),ErrorText,OKText)) -> BLANK | G2: 表-2 所有驱动系统10cm以内的碳纤维部件（在表-1中未体现）All carbon fiber parts with in 10cm of TS (not listed in table-1) | I2: =IF(COUNTIF(I3:I14,"="&IncompleteText),IncompleteText,IF(COUNTIF(I3:I14,"="&ErrorText),ErrorText,OKText)) -> BLANK | K2: 所有驱动系统壳体（在表-1及表-2中未体现）All TS enclosure (not listed in table 1 and 2) | O2: =IF(COUNTIF(O3:O14,"="&IncompleteText),IncompleteText,IF(COUNTIF(O3:O14,"="&ErrorText),ErrorText,OKText)) -> BLANK
A3: 位置 Parts | B3: 材料类型 Type of Materials | C3: 接地点说明图片 Grounding Point picture | D3: 承受电流强度 Ampacity [A] | G3: 位置 Parts | H3: 接地点说明图片 Grounding Point picture | K3: 位置 | L3: 材料 | M3: 接地点说明图片
A4: 主环 Main hoop | B4: 导电 Conductive | C4: 请将图片控制在此单元格范围内，并在单元格内填写TRUE Place the picture in this cell, and replace texts in this cell as 'True' | E4: {=IF(ISBLANK(D4),IncompleteText,IF(AND(C4,D4>=0.1*FuseNoiCur),OKText,ErrorText))} -> BLANK | G4: 部件 parts | H4: 请将图片控制在此单元格范围内，并在单元格内填写TRUE 如果确实无任何填写的部件，请在此填写TRUE 请将图片控制在此单元格范围内，并在单元格内填写TRUE Place the picture in this cell, and replace texts in this cell as 'True' If not parts in this table, also fill this cell as "True" | I4: =IF(ISERROR(IF(ISBLANK(G4),IncompleteText,IF(H4,OKText,IncompleteText))),IncompleteText,IF(ISBLANK(G4),IncompleteText,IF(H4,OKText,IncompleteText))) -> BLANK | K4: 部件 parts | M4: 请将图片控制在此单元格范围内，并在单元格内填写TRUE 如果确实无任何填写的部件，请在此填写TRUE 请将图片控制在此单元格范围内，并在单元格内填写TRUE Place the picture in this cell, and replace texts in this cell as 'True' If not parts in this table, also fill this cell as "True" | N4: 如果不是”导电”材料，本格留空 N/A if not conductive | O4: =IF(ISERROR(IF(L4="导电",IF(ISBLANK(N4),IncompleteText,IF(AND(M4,N4>=0.1*FuseNoiCur),OKText,ErrorText)),IF(M4,OKText,ErrorText))),IncompleteText,IF(L4="导电",IF(ISBLANK(N4),IncompleteText,IF(AND(M4,N4>=0.1*FuseNoiCur),OKText,ErrorText)),IF(M4,OKText,ErrorText))) -> BLANK
